[36m[2025-03-18 12:28:49 DEBUG] [__init__:101][39m ###############################################################################
[36m[2025-03-18 12:28:49 DEBUG] [__init__:102][39m Running command 'run'
[36m[2025-03-18 12:28:49 DEBUG] [__init__:106][39m Using settings file '/home/mmc/.chaostoolkit/settings.yaml'
[36m[2025-03-18 12:28:49 DEBUG] [settings:31][39m The Chaos Toolkit settings file could not be found at '/home/mmc/.chaostoolkit/settings.yaml'.
[36m[2025-03-18 12:28:49 DEBUG] [__init__:472][39m No controls to apply on 'loader'
[36m[2025-03-18 12:28:49 DEBUG] [__init__:472][39m No controls to apply on 'loader'
[36m[2025-03-18 12:28:49 DEBUG] [caching:24][39m Building activity cache...
[36m[2025-03-18 12:28:49 DEBUG] [caching:35][39m Cached 3 activities
[32m[2025-03-18 12:28:49 INFO] [experiment:59][39m Validating the experiment's syntax
[36m[2025-03-18 12:28:49 DEBUG] [configuration:64][39m Loading configuration...
[36m[2025-03-18 12:28:49 DEBUG] [secret:79][39m Loading secrets...
[36m[2025-03-18 12:28:49 DEBUG] [secret:104][39m Done loading secrets
[32m[2025-03-18 12:28:49 INFO] [experiment:112][39m Experiment looks valid
[36m[2025-03-18 12:28:49 DEBUG] [caching:42][39m Clearing activities cache
[36m[2025-03-18 12:28:49 DEBUG] [run:224][39m Runtime strategies: hypothesis - default / rollbacks - default
[36m[2025-03-18 12:28:49 DEBUG] [caching:24][39m Building activity cache...
[36m[2025-03-18 12:28:49 DEBUG] [caching:35][39m Cached 3 activities
[36m[2025-03-18 12:28:49 DEBUG] [configuration:64][39m Loading configuration...
[36m[2025-03-18 12:28:49 DEBUG] [secret:79][39m Loading secrets...
[36m[2025-03-18 12:28:49 DEBUG] [secret:104][39m Done loading secrets
[36m[2025-03-18 12:28:49 DEBUG] [configuration:161][39m Loading dynamic configuration...
[32m[2025-03-18 12:28:49 INFO] [run:440][39m Running experiment: Privelege Scalation
[36m[2025-03-18 12:28:49 DEBUG] [__init__:67][39m Initializing controls
[32m[2025-03-18 12:28:49 INFO] [run:471][39m Steady-state strategy: default
[32m[2025-03-18 12:28:49 INFO] [run:477][39m Rollbacks strategy: default
[36m[2025-03-18 12:28:49 DEBUG] [__init__:472][39m No controls to apply on 'experiment'
[36m[2025-03-18 12:28:49 DEBUG] [run:654][39m Running steady-state hypothesis before the method
[32m[2025-03-18 12:28:49 INFO] [hypothesis:205][39m Steady state hypothesis: AWS GuardDuty detects the use of an instance profile credentials
[36m[2025-03-18 12:28:49 DEBUG] [__init__:472][39m No controls to apply on 'hypothesis'
[36m[2025-03-18 12:28:49 DEBUG] [__init__:472][39m No controls to apply on 'activity'
[32m[2025-03-18 12:28:49 INFO] [activity:232][39m Probe: GuarDuty-Findings
[36m[2025-03-18 12:28:49 DEBUG] [python:33][39m Activity 'GuarDuty-Findings' loaded from '/home/mmc/Descargas/devsecops-adversary-llm/SCE_Experiment/Runner/chaostk/lib/python3.12/site-packages/chaosaws/ec2/probes.py'
[36m[2025-03-18 12:28:49 DEBUG] [activity:260][39m   => succeeded with 'True'
[36m[2025-03-18 12:28:49 DEBUG] [__init__:472][39m No controls to apply on 'activity'
[36m[2025-03-18 12:28:49 DEBUG] [hypothesis:247][39m allowed tolerance is True
[32m[2025-03-18 12:28:49 INFO] [hypothesis:260][39m Steady state hypothesis is met!
[36m[2025-03-18 12:28:49 DEBUG] [__init__:472][39m No controls to apply on 'hypothesis'
[32m[2025-03-18 12:28:49 INFO] [run:778][39m Playing your experiment's method now...
[36m[2025-03-18 12:28:49 DEBUG] [__init__:472][39m No controls to apply on 'method'
[36m[2025-03-18 12:28:49 DEBUG] [__init__:472][39m No controls to apply on 'activity'
[32m[2025-03-18 12:28:49 INFO] [activity:232][39m Action: Creating_instance
[36m[2025-03-18 12:28:49 DEBUG] [python:33][39m Activity 'Creating_instance' loaded from '/home/mmc/Descargas/devsecops-adversary-llm/SCE_Experiment/Runner/chaostk/lib/python3.12/site-packages/chaosaws/ec2/actions.py'
[36m[2025-03-18 12:28:50 DEBUG] [activity:260][39m   => succeeded with 'False'
[36m[2025-03-18 12:28:50 DEBUG] [__init__:472][39m No controls to apply on 'activity'
[36m[2025-03-18 12:28:50 DEBUG] [__init__:472][39m No controls to apply on 'activity'
[32m[2025-03-18 12:28:50 INFO] [activity:232][39m Action: *******Extracting/Using credentials*******
[36m[2025-03-18 12:28:50 DEBUG] [python:33][39m Activity '*******Extracting/Using credentials*******' loaded from '/home/mmc/Descargas/devsecops-adversary-llm/SCE_Experiment/Runner/chaostk/lib/python3.12/site-packages/chaosaws/ec2/actions.py'
[36m[2025-03-18 12:28:50 DEBUG] [activity:317][39m Activity failed
    Traceback (most recent call last):
      File "/home/mmc/Descargas/devsecops-adversary-llm/SCE_Experiment/Runner/chaostk/lib/python3.12/site-packages/chaoslib/provider/python.py", line 56, in run_python_activity
        return func(**arguments)
               ^^^^^^^^^^^^^^^^^
      File "/home/mmc/Descargas/devsecops-adversary-llm/SCE_Experiment/Runner/chaostk/lib/python3.12/site-packages/chaosaws/ec2/actions.py", line 87, in extract_credentials_file
        with open(keys) as f:
             ^^^^^^^^^^
    FileNotFoundError: [Errno 2] No such file or directory: 'salida_remota.json'
    
    During handling of the above exception, another exception occurred:
    
    Traceback (most recent call last):
      File "/home/mmc/Descargas/devsecops-adversary-llm/SCE_Experiment/Runner/chaostk/lib/python3.12/site-packages/chaoslib/activity.py", line 310, in run_activity
        result = run_python_activity(activity, configuration, secrets)
                 ^^^^^^^^^^^^^^^^^^^^^^^^^^^^^^^^^^^^^^^^^^^^^^^^^^^^^
      File "/home/mmc/Descargas/devsecops-adversary-llm/SCE_Experiment/Runner/chaostk/lib/python3.12/site-packages/chaoslib/provider/python.py", line 58, in run_python_activity
        raise ActivityFailed(
      File "/home/mmc/Descargas/devsecops-adversary-llm/SCE_Experiment/Runner/chaostk/lib/python3.12/site-packages/chaoslib/provider/python.py", line 56, in run_python_activity
        return func(**arguments)
               ^^^^^^^^^^^^^^^^^
      File "/home/mmc/Descargas/devsecops-adversary-llm/SCE_Experiment/Runner/chaostk/lib/python3.12/site-packages/chaosaws/ec2/actions.py", line 87, in extract_credentials_file
        with open(keys) as f:
             ^^^^^^^^^^
    chaoslib.exceptions.ActivityFailed: FileNotFoundError: [Errno 2] No such file or directory: 'salida_remota.json'
[31m[2025-03-18 12:28:50 ERROR] [activity:268][39m   => failed: FileNotFoundError: [Errno 2] No such file or directory: 'salida_remota.json'
[36m[2025-03-18 12:28:50 DEBUG] [__init__:472][39m No controls to apply on 'activity'
[36m[2025-03-18 12:28:50 DEBUG] [__init__:472][39m No controls to apply on 'method'
[36m[2025-03-18 12:28:50 DEBUG] [run:696][39m Running steady-state hypothesis after the method
[32m[2025-03-18 12:28:50 INFO] [hypothesis:205][39m Steady state hypothesis: AWS GuardDuty detects the use of an instance profile credentials
[36m[2025-03-18 12:28:50 DEBUG] [__init__:472][39m No controls to apply on 'hypothesis'
[36m[2025-03-18 12:28:50 DEBUG] [__init__:472][39m No controls to apply on 'activity'
[32m[2025-03-18 12:28:50 INFO] [activity:232][39m Probe: GuarDuty-Findings
[36m[2025-03-18 12:28:50 DEBUG] [python:33][39m Activity 'GuarDuty-Findings' loaded from '/home/mmc/Descargas/devsecops-adversary-llm/SCE_Experiment/Runner/chaostk/lib/python3.12/site-packages/chaosaws/ec2/probes.py'
[36m[2025-03-18 12:28:50 DEBUG] [activity:260][39m   => succeeded with 'True'
[36m[2025-03-18 12:28:50 DEBUG] [__init__:472][39m No controls to apply on 'activity'
[36m[2025-03-18 12:28:50 DEBUG] [hypothesis:247][39m allowed tolerance is True
[32m[2025-03-18 12:28:50 INFO] [hypothesis:260][39m Steady state hypothesis is met!
[36m[2025-03-18 12:28:50 DEBUG] [__init__:472][39m No controls to apply on 'hypothesis'
[32m[2025-03-18 12:28:50 INFO] [run:1072][39m Let's rollback...
[36m[2025-03-18 12:28:50 DEBUG] [__init__:472][39m No controls to apply on 'rollback'
[32m[2025-03-18 12:28:50 INFO] [rollback:33][39m No declared rollbacks, let's move on.
[36m[2025-03-18 12:28:50 DEBUG] [__init__:472][39m No controls to apply on 'rollback'
[32m[2025-03-18 12:28:50 INFO] [run:598][39m Experiment ended with status: completed
[36m[2025-03-18 12:28:50 DEBUG] [__init__:472][39m No controls to apply on 'experiment'
[36m[2025-03-18 12:28:50 DEBUG] [__init__:106][39m Cleaning up controls
[36m[2025-03-18 12:28:50 DEBUG] [caching:42][39m Clearing activities cache
[36m[2025-03-18 12:35:23 DEBUG] [__init__:101][39m ###############################################################################
[36m[2025-03-18 12:35:23 DEBUG] [__init__:102][39m Running command 'run'
[36m[2025-03-18 12:35:23 DEBUG] [__init__:106][39m Using settings file '/home/mmc/.chaostoolkit/settings.yaml'
[36m[2025-03-18 12:35:23 DEBUG] [settings:31][39m The Chaos Toolkit settings file could not be found at '/home/mmc/.chaostoolkit/settings.yaml'.
[36m[2025-03-18 12:35:23 DEBUG] [__init__:472][39m No controls to apply on 'loader'
[36m[2025-03-18 12:35:23 DEBUG] [__init__:472][39m No controls to apply on 'loader'
[36m[2025-03-18 12:35:23 DEBUG] [caching:24][39m Building activity cache...
[36m[2025-03-18 12:35:23 DEBUG] [caching:35][39m Cached 3 activities
[32m[2025-03-18 12:35:23 INFO] [experiment:59][39m Validating the experiment's syntax
[36m[2025-03-18 12:35:23 DEBUG] [configuration:64][39m Loading configuration...
[36m[2025-03-18 12:35:23 DEBUG] [secret:79][39m Loading secrets...
[36m[2025-03-18 12:35:23 DEBUG] [secret:104][39m Done loading secrets
[32m[2025-03-18 12:35:23 INFO] [experiment:112][39m Experiment looks valid
[36m[2025-03-18 12:35:23 DEBUG] [caching:42][39m Clearing activities cache
[36m[2025-03-18 12:35:23 DEBUG] [run:224][39m Runtime strategies: hypothesis - default / rollbacks - default
[36m[2025-03-18 12:35:23 DEBUG] [caching:24][39m Building activity cache...
[36m[2025-03-18 12:35:23 DEBUG] [caching:35][39m Cached 3 activities
[36m[2025-03-18 12:35:23 DEBUG] [configuration:64][39m Loading configuration...
[36m[2025-03-18 12:35:23 DEBUG] [secret:79][39m Loading secrets...
[36m[2025-03-18 12:35:23 DEBUG] [secret:104][39m Done loading secrets
[36m[2025-03-18 12:35:23 DEBUG] [configuration:161][39m Loading dynamic configuration...
[32m[2025-03-18 12:35:23 INFO] [run:440][39m Running experiment: Privelege Scalation
[36m[2025-03-18 12:35:23 DEBUG] [__init__:67][39m Initializing controls
[32m[2025-03-18 12:35:23 INFO] [run:471][39m Steady-state strategy: default
[32m[2025-03-18 12:35:23 INFO] [run:477][39m Rollbacks strategy: default
[36m[2025-03-18 12:35:23 DEBUG] [__init__:472][39m No controls to apply on 'experiment'
[36m[2025-03-18 12:35:23 DEBUG] [run:654][39m Running steady-state hypothesis before the method
[32m[2025-03-18 12:35:23 INFO] [hypothesis:205][39m Steady state hypothesis: AWS GuardDuty detects the use of an instance profile credentials
[36m[2025-03-18 12:35:23 DEBUG] [__init__:472][39m No controls to apply on 'hypothesis'
[36m[2025-03-18 12:35:23 DEBUG] [__init__:472][39m No controls to apply on 'activity'
[32m[2025-03-18 12:35:23 INFO] [activity:232][39m Probe: GuarDuty-Findings
[36m[2025-03-18 12:35:23 DEBUG] [python:33][39m Activity 'GuarDuty-Findings' loaded from '/home/mmc/Descargas/devsecops-adversary-llm/SCE_Experiment/Runner/chaostk/lib/python3.12/site-packages/chaosaws/ec2/probes.py'
[36m[2025-03-18 12:35:23 DEBUG] [activity:260][39m   => succeeded with 'True'
[36m[2025-03-18 12:35:23 DEBUG] [__init__:472][39m No controls to apply on 'activity'
[36m[2025-03-18 12:35:23 DEBUG] [hypothesis:247][39m allowed tolerance is True
[32m[2025-03-18 12:35:23 INFO] [hypothesis:260][39m Steady state hypothesis is met!
[36m[2025-03-18 12:35:23 DEBUG] [__init__:472][39m No controls to apply on 'hypothesis'
[32m[2025-03-18 12:35:23 INFO] [run:778][39m Playing your experiment's method now...
[36m[2025-03-18 12:35:23 DEBUG] [__init__:472][39m No controls to apply on 'method'
[36m[2025-03-18 12:35:23 DEBUG] [__init__:472][39m No controls to apply on 'activity'
[32m[2025-03-18 12:35:23 INFO] [activity:232][39m Action: Creating_instance
[36m[2025-03-18 12:35:23 DEBUG] [python:33][39m Activity 'Creating_instance' loaded from '/home/mmc/Descargas/devsecops-adversary-llm/SCE_Experiment/Runner/chaostk/lib/python3.12/site-packages/chaosaws/ec2/actions.py'
[36m[2025-03-18 12:35:24 DEBUG] [activity:260][39m   => succeeded with 'False'
[36m[2025-03-18 12:35:24 DEBUG] [__init__:472][39m No controls to apply on 'activity'
[36m[2025-03-18 12:35:24 DEBUG] [__init__:472][39m No controls to apply on 'activity'
[32m[2025-03-18 12:35:24 INFO] [activity:232][39m Action: *******Extracting/Using credentials*******
[36m[2025-03-18 12:35:24 DEBUG] [python:33][39m Activity '*******Extracting/Using credentials*******' loaded from '/home/mmc/Descargas/devsecops-adversary-llm/SCE_Experiment/Runner/chaostk/lib/python3.12/site-packages/chaosaws/ec2/actions.py'
[36m[2025-03-18 12:35:24 DEBUG] [activity:317][39m Activity failed
    Traceback (most recent call last):
      File "/home/mmc/Descargas/devsecops-adversary-llm/SCE_Experiment/Runner/chaostk/lib/python3.12/site-packages/chaoslib/provider/python.py", line 56, in run_python_activity
        return func(**arguments)
               ^^^^^^^^^^^^^^^^^
      File "/home/mmc/Descargas/devsecops-adversary-llm/SCE_Experiment/Runner/chaostk/lib/python3.12/site-packages/chaosaws/ec2/actions.py", line 87, in extract_credentials_file
        with open(keys) as f:
             ^^^^^^^^^^
    FileNotFoundError: [Errno 2] No such file or directory: 'remote_output.json'
    
    During handling of the above exception, another exception occurred:
    
    Traceback (most recent call last):
      File "/home/mmc/Descargas/devsecops-adversary-llm/SCE_Experiment/Runner/chaostk/lib/python3.12/site-packages/chaoslib/activity.py", line 310, in run_activity
        result = run_python_activity(activity, configuration, secrets)
                 ^^^^^^^^^^^^^^^^^^^^^^^^^^^^^^^^^^^^^^^^^^^^^^^^^^^^^
      File "/home/mmc/Descargas/devsecops-adversary-llm/SCE_Experiment/Runner/chaostk/lib/python3.12/site-packages/chaoslib/provider/python.py", line 58, in run_python_activity
        raise ActivityFailed(
      File "/home/mmc/Descargas/devsecops-adversary-llm/SCE_Experiment/Runner/chaostk/lib/python3.12/site-packages/chaoslib/provider/python.py", line 56, in run_python_activity
        return func(**arguments)
               ^^^^^^^^^^^^^^^^^
      File "/home/mmc/Descargas/devsecops-adversary-llm/SCE_Experiment/Runner/chaostk/lib/python3.12/site-packages/chaosaws/ec2/actions.py", line 87, in extract_credentials_file
        with open(keys) as f:
             ^^^^^^^^^^
    chaoslib.exceptions.ActivityFailed: FileNotFoundError: [Errno 2] No such file or directory: 'remote_output.json'
[31m[2025-03-18 12:35:24 ERROR] [activity:268][39m   => failed: FileNotFoundError: [Errno 2] No such file or directory: 'remote_output.json'
[36m[2025-03-18 12:35:24 DEBUG] [__init__:472][39m No controls to apply on 'activity'
[36m[2025-03-18 12:35:24 DEBUG] [__init__:472][39m No controls to apply on 'method'
[36m[2025-03-18 12:35:24 DEBUG] [run:696][39m Running steady-state hypothesis after the method
[32m[2025-03-18 12:35:24 INFO] [hypothesis:205][39m Steady state hypothesis: AWS GuardDuty detects the use of an instance profile credentials
[36m[2025-03-18 12:35:24 DEBUG] [__init__:472][39m No controls to apply on 'hypothesis'
[36m[2025-03-18 12:35:24 DEBUG] [__init__:472][39m No controls to apply on 'activity'
[32m[2025-03-18 12:35:24 INFO] [activity:232][39m Probe: GuarDuty-Findings
[36m[2025-03-18 12:35:24 DEBUG] [python:33][39m Activity 'GuarDuty-Findings' loaded from '/home/mmc/Descargas/devsecops-adversary-llm/SCE_Experiment/Runner/chaostk/lib/python3.12/site-packages/chaosaws/ec2/probes.py'
[36m[2025-03-18 12:35:24 DEBUG] [activity:260][39m   => succeeded with 'True'
[36m[2025-03-18 12:35:24 DEBUG] [__init__:472][39m No controls to apply on 'activity'
[36m[2025-03-18 12:35:24 DEBUG] [hypothesis:247][39m allowed tolerance is True
[32m[2025-03-18 12:35:24 INFO] [hypothesis:260][39m Steady state hypothesis is met!
[36m[2025-03-18 12:35:24 DEBUG] [__init__:472][39m No controls to apply on 'hypothesis'
[32m[2025-03-18 12:35:24 INFO] [run:1072][39m Let's rollback...
[36m[2025-03-18 12:35:24 DEBUG] [__init__:472][39m No controls to apply on 'rollback'
[32m[2025-03-18 12:35:24 INFO] [rollback:33][39m No declared rollbacks, let's move on.
[36m[2025-03-18 12:35:24 DEBUG] [__init__:472][39m No controls to apply on 'rollback'
[32m[2025-03-18 12:35:24 INFO] [run:598][39m Experiment ended with status: completed
[36m[2025-03-18 12:35:24 DEBUG] [__init__:472][39m No controls to apply on 'experiment'
[36m[2025-03-18 12:35:24 DEBUG] [__init__:106][39m Cleaning up controls
[36m[2025-03-18 12:35:24 DEBUG] [caching:42][39m Clearing activities cache
[36m[2025-03-18 12:44:22 DEBUG] [__init__:101][39m ###############################################################################
[36m[2025-03-18 12:44:22 DEBUG] [__init__:102][39m Running command 'run'
[36m[2025-03-18 12:44:22 DEBUG] [__init__:106][39m Using settings file '/home/mmc/.chaostoolkit/settings.yaml'
[36m[2025-03-18 12:44:22 DEBUG] [settings:31][39m The Chaos Toolkit settings file could not be found at '/home/mmc/.chaostoolkit/settings.yaml'.
[36m[2025-03-18 12:44:22 DEBUG] [__init__:472][39m No controls to apply on 'loader'
[36m[2025-03-18 12:44:22 DEBUG] [__init__:472][39m No controls to apply on 'loader'
[36m[2025-03-18 12:44:22 DEBUG] [caching:24][39m Building activity cache...
[36m[2025-03-18 12:44:22 DEBUG] [caching:35][39m Cached 3 activities
[32m[2025-03-18 12:44:22 INFO] [experiment:59][39m Validating the experiment's syntax
[36m[2025-03-18 12:44:22 DEBUG] [configuration:64][39m Loading configuration...
[36m[2025-03-18 12:44:22 DEBUG] [secret:79][39m Loading secrets...
[36m[2025-03-18 12:44:22 DEBUG] [secret:104][39m Done loading secrets
[32m[2025-03-18 12:44:22 INFO] [experiment:112][39m Experiment looks valid
[36m[2025-03-18 12:44:22 DEBUG] [caching:42][39m Clearing activities cache
[36m[2025-03-18 12:44:22 DEBUG] [run:224][39m Runtime strategies: hypothesis - default / rollbacks - default
[36m[2025-03-18 12:44:22 DEBUG] [caching:24][39m Building activity cache...
[36m[2025-03-18 12:44:22 DEBUG] [caching:35][39m Cached 3 activities
[36m[2025-03-18 12:44:22 DEBUG] [configuration:64][39m Loading configuration...
[36m[2025-03-18 12:44:22 DEBUG] [secret:79][39m Loading secrets...
[36m[2025-03-18 12:44:22 DEBUG] [secret:104][39m Done loading secrets
[36m[2025-03-18 12:44:22 DEBUG] [configuration:161][39m Loading dynamic configuration...
[32m[2025-03-18 12:44:22 INFO] [run:440][39m Running experiment: Privelege Scalation
[36m[2025-03-18 12:44:22 DEBUG] [__init__:67][39m Initializing controls
[32m[2025-03-18 12:44:22 INFO] [run:471][39m Steady-state strategy: default
[32m[2025-03-18 12:44:22 INFO] [run:477][39m Rollbacks strategy: default
[36m[2025-03-18 12:44:22 DEBUG] [__init__:472][39m No controls to apply on 'experiment'
[36m[2025-03-18 12:44:22 DEBUG] [run:654][39m Running steady-state hypothesis before the method
[32m[2025-03-18 12:44:22 INFO] [hypothesis:205][39m Steady state hypothesis: AWS GuardDuty detects the use of an instance profile credentials
[36m[2025-03-18 12:44:22 DEBUG] [__init__:472][39m No controls to apply on 'hypothesis'
[36m[2025-03-18 12:44:22 DEBUG] [__init__:472][39m No controls to apply on 'activity'
[32m[2025-03-18 12:44:22 INFO] [activity:232][39m Probe: GuarDuty-Findings
[36m[2025-03-18 12:44:22 DEBUG] [python:33][39m Activity 'GuarDuty-Findings' loaded from '/home/mmc/Descargas/devsecops-adversary-llm/SCE_Experiment/Runner/chaostk/lib/python3.12/site-packages/chaosaws/ec2/probes.py'
[36m[2025-03-18 12:44:22 DEBUG] [activity:260][39m   => succeeded with 'True'
[36m[2025-03-18 12:44:22 DEBUG] [__init__:472][39m No controls to apply on 'activity'
[36m[2025-03-18 12:44:22 DEBUG] [hypothesis:247][39m allowed tolerance is True
[32m[2025-03-18 12:44:22 INFO] [hypothesis:260][39m Steady state hypothesis is met!
[36m[2025-03-18 12:44:22 DEBUG] [__init__:472][39m No controls to apply on 'hypothesis'
[32m[2025-03-18 12:44:22 INFO] [run:778][39m Playing your experiment's method now...
[36m[2025-03-18 12:44:22 DEBUG] [__init__:472][39m No controls to apply on 'method'
[36m[2025-03-18 12:44:22 DEBUG] [__init__:472][39m No controls to apply on 'activity'
[32m[2025-03-18 12:44:22 INFO] [activity:232][39m Action: Creating_instance
[36m[2025-03-18 12:44:22 DEBUG] [python:33][39m Activity 'Creating_instance' loaded from '/home/mmc/Descargas/devsecops-adversary-llm/SCE_Experiment/Runner/chaostk/lib/python3.12/site-packages/chaosaws/ec2/actions.py'
[36m[2025-03-18 12:48:14 DEBUG] [__init__:472][39m No controls to apply on 'activity'
[36m[2025-03-18 12:48:14 DEBUG] [__init__:472][39m No controls to apply on 'method'
[33m[2025-03-18 12:48:14 WARNING] [run:556][39m Received a termination signal (Ctrl-C)...
[32m[2025-03-18 12:48:14 INFO] [run:598][39m Experiment ended with status: interrupted
[36m[2025-03-18 12:48:14 DEBUG] [__init__:472][39m No controls to apply on 'experiment'
[36m[2025-03-18 12:48:14 DEBUG] [__init__:106][39m Cleaning up controls
[36m[2025-03-18 12:48:14 DEBUG] [caching:42][39m Clearing activities cache
[36m[2025-03-18 13:06:19 DEBUG] [__init__:101][39m ###############################################################################
[36m[2025-03-18 13:06:19 DEBUG] [__init__:102][39m Running command 'run'
[36m[2025-03-18 13:06:19 DEBUG] [__init__:106][39m Using settings file '/home/mmc/.chaostoolkit/settings.yaml'
[36m[2025-03-18 13:06:19 DEBUG] [settings:31][39m The Chaos Toolkit settings file could not be found at '/home/mmc/.chaostoolkit/settings.yaml'.
[36m[2025-03-18 13:06:19 DEBUG] [__init__:472][39m No controls to apply on 'loader'
[36m[2025-03-18 13:06:19 DEBUG] [__init__:472][39m No controls to apply on 'loader'
[36m[2025-03-18 13:06:19 DEBUG] [caching:24][39m Building activity cache...
[36m[2025-03-18 13:06:19 DEBUG] [caching:35][39m Cached 3 activities
[32m[2025-03-18 13:06:19 INFO] [experiment:59][39m Validating the experiment's syntax
[36m[2025-03-18 13:06:19 DEBUG] [configuration:64][39m Loading configuration...
[36m[2025-03-18 13:06:19 DEBUG] [secret:79][39m Loading secrets...
[36m[2025-03-18 13:06:19 DEBUG] [secret:104][39m Done loading secrets
[32m[2025-03-18 13:06:19 INFO] [experiment:112][39m Experiment looks valid
[36m[2025-03-18 13:06:19 DEBUG] [caching:42][39m Clearing activities cache
[36m[2025-03-18 13:06:19 DEBUG] [run:224][39m Runtime strategies: hypothesis - default / rollbacks - default
[36m[2025-03-18 13:06:19 DEBUG] [caching:24][39m Building activity cache...
[36m[2025-03-18 13:06:19 DEBUG] [caching:35][39m Cached 3 activities
[36m[2025-03-18 13:06:19 DEBUG] [configuration:64][39m Loading configuration...
[36m[2025-03-18 13:06:19 DEBUG] [secret:79][39m Loading secrets...
[36m[2025-03-18 13:06:19 DEBUG] [secret:104][39m Done loading secrets
[36m[2025-03-18 13:06:19 DEBUG] [configuration:161][39m Loading dynamic configuration...
[32m[2025-03-18 13:06:19 INFO] [run:440][39m Running experiment: Privelege Scalation
[36m[2025-03-18 13:06:19 DEBUG] [__init__:67][39m Initializing controls
[32m[2025-03-18 13:06:19 INFO] [run:471][39m Steady-state strategy: default
[32m[2025-03-18 13:06:19 INFO] [run:477][39m Rollbacks strategy: default
[36m[2025-03-18 13:06:19 DEBUG] [__init__:472][39m No controls to apply on 'experiment'
[36m[2025-03-18 13:06:19 DEBUG] [run:654][39m Running steady-state hypothesis before the method
[32m[2025-03-18 13:06:19 INFO] [hypothesis:205][39m Steady state hypothesis: AWS GuardDuty detects the use of an instance profile credentials
[36m[2025-03-18 13:06:19 DEBUG] [__init__:472][39m No controls to apply on 'hypothesis'
[36m[2025-03-18 13:06:19 DEBUG] [__init__:472][39m No controls to apply on 'activity'
[32m[2025-03-18 13:06:19 INFO] [activity:232][39m Probe: GuarDuty-Findings
[36m[2025-03-18 13:06:19 DEBUG] [python:33][39m Activity 'GuarDuty-Findings' loaded from '/home/mmc/Descargas/devsecops-adversary-llm/SCE_Experiment/Runner/chaostk/lib/python3.12/site-packages/chaosaws/ec2/probes.py'
[36m[2025-03-18 13:06:19 DEBUG] [activity:260][39m   => succeeded with 'True'
[36m[2025-03-18 13:06:19 DEBUG] [__init__:472][39m No controls to apply on 'activity'
[36m[2025-03-18 13:06:19 DEBUG] [hypothesis:247][39m allowed tolerance is True
[32m[2025-03-18 13:06:19 INFO] [hypothesis:260][39m Steady state hypothesis is met!
[36m[2025-03-18 13:06:19 DEBUG] [__init__:472][39m No controls to apply on 'hypothesis'
[32m[2025-03-18 13:06:19 INFO] [run:778][39m Playing your experiment's method now...
[36m[2025-03-18 13:06:19 DEBUG] [__init__:472][39m No controls to apply on 'method'
[36m[2025-03-18 13:06:19 DEBUG] [__init__:472][39m No controls to apply on 'activity'
[32m[2025-03-18 13:06:19 INFO] [activity:232][39m Action: Creating_instance
[36m[2025-03-18 13:06:19 DEBUG] [python:33][39m Activity 'Creating_instance' loaded from '/home/mmc/Descargas/devsecops-adversary-llm/SCE_Experiment/Runner/chaostk/lib/python3.12/site-packages/chaosaws/ec2/actions.py'
[36m[2025-03-18 13:06:21 DEBUG] [activity:260][39m   => succeeded with 'False'
[36m[2025-03-18 13:06:21 DEBUG] [__init__:472][39m No controls to apply on 'activity'
[36m[2025-03-18 13:06:21 DEBUG] [__init__:472][39m No controls to apply on 'activity'
[32m[2025-03-18 13:06:21 INFO] [activity:232][39m Action: *******Extracting/Using credentials*******
[36m[2025-03-18 13:06:21 DEBUG] [python:33][39m Activity '*******Extracting/Using credentials*******' loaded from '/home/mmc/Descargas/devsecops-adversary-llm/SCE_Experiment/Runner/chaostk/lib/python3.12/site-packages/chaosaws/ec2/actions.py'
[36m[2025-03-18 13:06:21 DEBUG] [activity:317][39m Activity failed
    Traceback (most recent call last):
      File "/home/mmc/Descargas/devsecops-adversary-llm/SCE_Experiment/Runner/chaostk/lib/python3.12/site-packages/chaoslib/provider/python.py", line 56, in run_python_activity
        return func(**arguments)
               ^^^^^^^^^^^^^^^^^
      File "/home/mmc/Descargas/devsecops-adversary-llm/SCE_Experiment/Runner/chaostk/lib/python3.12/site-packages/chaosaws/ec2/actions.py", line 89, in extract_credentials_file
        with open(keys) as f:
             ^^^^^^^^^^
    FileNotFoundError: [Errno 2] No such file or directory: 'remote_output.json'
    
    During handling of the above exception, another exception occurred:
    
    Traceback (most recent call last):
      File "/home/mmc/Descargas/devsecops-adversary-llm/SCE_Experiment/Runner/chaostk/lib/python3.12/site-packages/chaoslib/activity.py", line 310, in run_activity
        result = run_python_activity(activity, configuration, secrets)
                 ^^^^^^^^^^^^^^^^^^^^^^^^^^^^^^^^^^^^^^^^^^^^^^^^^^^^^
      File "/home/mmc/Descargas/devsecops-adversary-llm/SCE_Experiment/Runner/chaostk/lib/python3.12/site-packages/chaoslib/provider/python.py", line 58, in run_python_activity
        raise ActivityFailed(
      File "/home/mmc/Descargas/devsecops-adversary-llm/SCE_Experiment/Runner/chaostk/lib/python3.12/site-packages/chaoslib/provider/python.py", line 56, in run_python_activity
        return func(**arguments)
               ^^^^^^^^^^^^^^^^^
      File "/home/mmc/Descargas/devsecops-adversary-llm/SCE_Experiment/Runner/chaostk/lib/python3.12/site-packages/chaosaws/ec2/actions.py", line 89, in extract_credentials_file
        with open(keys) as f:
             ^^^^^^^^^^
    chaoslib.exceptions.ActivityFailed: FileNotFoundError: [Errno 2] No such file or directory: 'remote_output.json'
[31m[2025-03-18 13:06:21 ERROR] [activity:268][39m   => failed: FileNotFoundError: [Errno 2] No such file or directory: 'remote_output.json'
[36m[2025-03-18 13:06:21 DEBUG] [__init__:472][39m No controls to apply on 'activity'
[36m[2025-03-18 13:06:21 DEBUG] [__init__:472][39m No controls to apply on 'method'
[36m[2025-03-18 13:06:21 DEBUG] [run:696][39m Running steady-state hypothesis after the method
[32m[2025-03-18 13:06:21 INFO] [hypothesis:205][39m Steady state hypothesis: AWS GuardDuty detects the use of an instance profile credentials
[36m[2025-03-18 13:06:21 DEBUG] [__init__:472][39m No controls to apply on 'hypothesis'
[36m[2025-03-18 13:06:21 DEBUG] [__init__:472][39m No controls to apply on 'activity'
[32m[2025-03-18 13:06:21 INFO] [activity:232][39m Probe: GuarDuty-Findings
[36m[2025-03-18 13:06:21 DEBUG] [python:33][39m Activity 'GuarDuty-Findings' loaded from '/home/mmc/Descargas/devsecops-adversary-llm/SCE_Experiment/Runner/chaostk/lib/python3.12/site-packages/chaosaws/ec2/probes.py'
[36m[2025-03-18 13:06:21 DEBUG] [activity:260][39m   => succeeded with 'True'
[36m[2025-03-18 13:06:21 DEBUG] [__init__:472][39m No controls to apply on 'activity'
[36m[2025-03-18 13:06:21 DEBUG] [hypothesis:247][39m allowed tolerance is True
[32m[2025-03-18 13:06:21 INFO] [hypothesis:260][39m Steady state hypothesis is met!
[36m[2025-03-18 13:06:21 DEBUG] [__init__:472][39m No controls to apply on 'hypothesis'
[32m[2025-03-18 13:06:21 INFO] [run:1072][39m Let's rollback...
[36m[2025-03-18 13:06:21 DEBUG] [__init__:472][39m No controls to apply on 'rollback'
[32m[2025-03-18 13:06:21 INFO] [rollback:33][39m No declared rollbacks, let's move on.
[36m[2025-03-18 13:06:21 DEBUG] [__init__:472][39m No controls to apply on 'rollback'
[32m[2025-03-18 13:06:21 INFO] [run:598][39m Experiment ended with status: completed
[36m[2025-03-18 13:06:21 DEBUG] [__init__:472][39m No controls to apply on 'experiment'
[36m[2025-03-18 13:06:21 DEBUG] [__init__:106][39m Cleaning up controls
[36m[2025-03-18 13:06:21 DEBUG] [caching:42][39m Clearing activities cache
[36m[2025-03-18 13:07:05 DEBUG] [__init__:101][39m ###############################################################################
[36m[2025-03-18 13:07:05 DEBUG] [__init__:102][39m Running command 'run'
[36m[2025-03-18 13:07:05 DEBUG] [__init__:106][39m Using settings file '/home/mmc/.chaostoolkit/settings.yaml'
[36m[2025-03-18 13:07:05 DEBUG] [settings:31][39m The Chaos Toolkit settings file could not be found at '/home/mmc/.chaostoolkit/settings.yaml'.
[36m[2025-03-18 13:07:05 DEBUG] [__init__:472][39m No controls to apply on 'loader'
[36m[2025-03-18 13:07:05 DEBUG] [__init__:472][39m No controls to apply on 'loader'
[36m[2025-03-18 13:07:05 DEBUG] [caching:24][39m Building activity cache...
[36m[2025-03-18 13:07:05 DEBUG] [caching:35][39m Cached 3 activities
[32m[2025-03-18 13:07:05 INFO] [experiment:59][39m Validating the experiment's syntax
[36m[2025-03-18 13:07:05 DEBUG] [configuration:64][39m Loading configuration...
[36m[2025-03-18 13:07:05 DEBUG] [secret:79][39m Loading secrets...
[36m[2025-03-18 13:07:05 DEBUG] [secret:104][39m Done loading secrets
[32m[2025-03-18 13:07:05 INFO] [experiment:112][39m Experiment looks valid
[36m[2025-03-18 13:07:05 DEBUG] [caching:42][39m Clearing activities cache
[36m[2025-03-18 13:07:05 DEBUG] [run:224][39m Runtime strategies: hypothesis - default / rollbacks - default
[36m[2025-03-18 13:07:05 DEBUG] [caching:24][39m Building activity cache...
[36m[2025-03-18 13:07:05 DEBUG] [caching:35][39m Cached 3 activities
[36m[2025-03-18 13:07:05 DEBUG] [configuration:64][39m Loading configuration...
[36m[2025-03-18 13:07:05 DEBUG] [secret:79][39m Loading secrets...
[36m[2025-03-18 13:07:05 DEBUG] [secret:104][39m Done loading secrets
[36m[2025-03-18 13:07:05 DEBUG] [configuration:161][39m Loading dynamic configuration...
[32m[2025-03-18 13:07:05 INFO] [run:440][39m Running experiment: Privelege Scalation
[36m[2025-03-18 13:07:05 DEBUG] [__init__:67][39m Initializing controls
[32m[2025-03-18 13:07:05 INFO] [run:471][39m Steady-state strategy: default
[32m[2025-03-18 13:07:05 INFO] [run:477][39m Rollbacks strategy: default
[36m[2025-03-18 13:07:05 DEBUG] [__init__:472][39m No controls to apply on 'experiment'
[36m[2025-03-18 13:07:05 DEBUG] [run:654][39m Running steady-state hypothesis before the method
[32m[2025-03-18 13:07:05 INFO] [hypothesis:205][39m Steady state hypothesis: AWS GuardDuty detects the use of an instance profile credentials
[36m[2025-03-18 13:07:05 DEBUG] [__init__:472][39m No controls to apply on 'hypothesis'
[36m[2025-03-18 13:07:05 DEBUG] [__init__:472][39m No controls to apply on 'activity'
[32m[2025-03-18 13:07:05 INFO] [activity:232][39m Probe: GuarDuty-Findings
[36m[2025-03-18 13:07:05 DEBUG] [python:33][39m Activity 'GuarDuty-Findings' loaded from '/home/mmc/Descargas/devsecops-adversary-llm/SCE_Experiment/Runner/chaostk/lib/python3.12/site-packages/chaosaws/ec2/probes.py'
[36m[2025-03-18 13:07:05 DEBUG] [activity:260][39m   => succeeded with 'True'
[36m[2025-03-18 13:07:05 DEBUG] [__init__:472][39m No controls to apply on 'activity'
[36m[2025-03-18 13:07:05 DEBUG] [hypothesis:247][39m allowed tolerance is True
[32m[2025-03-18 13:07:05 INFO] [hypothesis:260][39m Steady state hypothesis is met!
[36m[2025-03-18 13:07:05 DEBUG] [__init__:472][39m No controls to apply on 'hypothesis'
[32m[2025-03-18 13:07:05 INFO] [run:778][39m Playing your experiment's method now...
[36m[2025-03-18 13:07:05 DEBUG] [__init__:472][39m No controls to apply on 'method'
[36m[2025-03-18 13:07:05 DEBUG] [__init__:472][39m No controls to apply on 'activity'
[32m[2025-03-18 13:07:05 INFO] [activity:232][39m Action: Creating_instance
[36m[2025-03-18 13:07:05 DEBUG] [python:33][39m Activity 'Creating_instance' loaded from '/home/mmc/Descargas/devsecops-adversary-llm/SCE_Experiment/Runner/chaostk/lib/python3.12/site-packages/chaosaws/ec2/actions.py'
[36m[2025-03-18 13:07:07 DEBUG] [__init__:472][39m No controls to apply on 'activity'
[36m[2025-03-18 13:07:07 DEBUG] [__init__:472][39m No controls to apply on 'method'
[33m[2025-03-18 13:07:07 WARNING] [run:556][39m Received a termination signal (Ctrl-C)...
[32m[2025-03-18 13:07:07 INFO] [run:598][39m Experiment ended with status: interrupted
[36m[2025-03-18 13:07:07 DEBUG] [__init__:472][39m No controls to apply on 'experiment'
[36m[2025-03-18 13:07:07 DEBUG] [__init__:106][39m Cleaning up controls
[36m[2025-03-18 13:07:07 DEBUG] [caching:42][39m Clearing activities cache
[36m[2025-03-18 13:08:24 DEBUG] [__init__:101][39m ###############################################################################
[36m[2025-03-18 13:08:24 DEBUG] [__init__:102][39m Running command 'run'
[36m[2025-03-18 13:08:24 DEBUG] [__init__:106][39m Using settings file '/home/mmc/.chaostoolkit/settings.yaml'
[36m[2025-03-18 13:08:24 DEBUG] [settings:31][39m The Chaos Toolkit settings file could not be found at '/home/mmc/.chaostoolkit/settings.yaml'.
[36m[2025-03-18 13:08:24 DEBUG] [__init__:472][39m No controls to apply on 'loader'
[36m[2025-03-18 13:08:24 DEBUG] [__init__:472][39m No controls to apply on 'loader'
[36m[2025-03-18 13:08:24 DEBUG] [caching:24][39m Building activity cache...
[36m[2025-03-18 13:08:24 DEBUG] [caching:35][39m Cached 3 activities
[32m[2025-03-18 13:08:24 INFO] [experiment:59][39m Validating the experiment's syntax
[36m[2025-03-18 13:08:24 DEBUG] [configuration:64][39m Loading configuration...
[36m[2025-03-18 13:08:24 DEBUG] [secret:79][39m Loading secrets...
[36m[2025-03-18 13:08:24 DEBUG] [secret:104][39m Done loading secrets
[32m[2025-03-18 13:08:24 INFO] [experiment:112][39m Experiment looks valid
[36m[2025-03-18 13:08:24 DEBUG] [caching:42][39m Clearing activities cache
[36m[2025-03-18 13:08:24 DEBUG] [run:224][39m Runtime strategies: hypothesis - default / rollbacks - default
[36m[2025-03-18 13:08:24 DEBUG] [caching:24][39m Building activity cache...
[36m[2025-03-18 13:08:24 DEBUG] [caching:35][39m Cached 3 activities
[36m[2025-03-18 13:08:24 DEBUG] [configuration:64][39m Loading configuration...
[36m[2025-03-18 13:08:24 DEBUG] [secret:79][39m Loading secrets...
[36m[2025-03-18 13:08:24 DEBUG] [secret:104][39m Done loading secrets
[36m[2025-03-18 13:08:24 DEBUG] [configuration:161][39m Loading dynamic configuration...
[32m[2025-03-18 13:08:24 INFO] [run:440][39m Running experiment: Privelege Scalation
[36m[2025-03-18 13:08:24 DEBUG] [__init__:67][39m Initializing controls
[32m[2025-03-18 13:08:24 INFO] [run:471][39m Steady-state strategy: default
[32m[2025-03-18 13:08:24 INFO] [run:477][39m Rollbacks strategy: default
[36m[2025-03-18 13:08:24 DEBUG] [__init__:472][39m No controls to apply on 'experiment'
[36m[2025-03-18 13:08:24 DEBUG] [run:654][39m Running steady-state hypothesis before the method
[32m[2025-03-18 13:08:24 INFO] [hypothesis:205][39m Steady state hypothesis: AWS GuardDuty detects the use of an instance profile credentials
[36m[2025-03-18 13:08:24 DEBUG] [__init__:472][39m No controls to apply on 'hypothesis'
[36m[2025-03-18 13:08:24 DEBUG] [__init__:472][39m No controls to apply on 'activity'
[32m[2025-03-18 13:08:24 INFO] [activity:232][39m Probe: GuarDuty-Findings
[36m[2025-03-18 13:08:24 DEBUG] [python:33][39m Activity 'GuarDuty-Findings' loaded from '/home/mmc/Descargas/devsecops-adversary-llm/SCE_Experiment/Runner/chaostk/lib/python3.12/site-packages/chaosaws/ec2/probes.py'
[36m[2025-03-18 13:08:24 DEBUG] [activity:260][39m   => succeeded with 'True'
[36m[2025-03-18 13:08:24 DEBUG] [__init__:472][39m No controls to apply on 'activity'
[36m[2025-03-18 13:08:24 DEBUG] [hypothesis:247][39m allowed tolerance is True
[32m[2025-03-18 13:08:24 INFO] [hypothesis:260][39m Steady state hypothesis is met!
[36m[2025-03-18 13:08:24 DEBUG] [__init__:472][39m No controls to apply on 'hypothesis'
[32m[2025-03-18 13:08:24 INFO] [run:778][39m Playing your experiment's method now...
[36m[2025-03-18 13:08:24 DEBUG] [__init__:472][39m No controls to apply on 'method'
[36m[2025-03-18 13:08:24 DEBUG] [__init__:472][39m No controls to apply on 'activity'
[32m[2025-03-18 13:08:24 INFO] [activity:232][39m Action: Creating_instance
[36m[2025-03-18 13:08:24 DEBUG] [python:33][39m Activity 'Creating_instance' loaded from '/home/mmc/Descargas/devsecops-adversary-llm/SCE_Experiment/Runner/chaostk/lib/python3.12/site-packages/chaosaws/ec2/actions.py'
[36m[2025-03-18 13:20:29 DEBUG] [__init__:472][39m No controls to apply on 'activity'
[36m[2025-03-18 13:20:29 DEBUG] [__init__:472][39m No controls to apply on 'method'
[33m[2025-03-18 13:20:29 WARNING] [run:556][39m Received a termination signal (Ctrl-C)...
[32m[2025-03-18 13:20:29 INFO] [run:598][39m Experiment ended with status: interrupted
[36m[2025-03-18 13:20:29 DEBUG] [__init__:472][39m No controls to apply on 'experiment'
[36m[2025-03-18 13:20:29 DEBUG] [__init__:106][39m Cleaning up controls
[36m[2025-03-18 13:20:29 DEBUG] [caching:42][39m Clearing activities cache
[36m[2025-03-18 13:23:51 DEBUG] [__init__:101][39m ###############################################################################
[36m[2025-03-18 13:23:51 DEBUG] [__init__:102][39m Running command 'run'
[36m[2025-03-18 13:23:51 DEBUG] [__init__:106][39m Using settings file '/home/mmc/.chaostoolkit/settings.yaml'
[36m[2025-03-18 13:23:51 DEBUG] [settings:31][39m The Chaos Toolkit settings file could not be found at '/home/mmc/.chaostoolkit/settings.yaml'.
[36m[2025-03-18 13:23:51 DEBUG] [__init__:472][39m No controls to apply on 'loader'
[36m[2025-03-18 13:23:51 DEBUG] [__init__:472][39m No controls to apply on 'loader'
[36m[2025-03-18 13:23:51 DEBUG] [caching:24][39m Building activity cache...
[36m[2025-03-18 13:23:51 DEBUG] [caching:35][39m Cached 3 activities
[32m[2025-03-18 13:23:51 INFO] [experiment:59][39m Validating the experiment's syntax
[36m[2025-03-18 13:23:51 DEBUG] [configuration:64][39m Loading configuration...
[36m[2025-03-18 13:23:51 DEBUG] [secret:79][39m Loading secrets...
[36m[2025-03-18 13:23:51 DEBUG] [secret:104][39m Done loading secrets
[32m[2025-03-18 13:23:51 INFO] [experiment:112][39m Experiment looks valid
[36m[2025-03-18 13:23:51 DEBUG] [caching:42][39m Clearing activities cache
[36m[2025-03-18 13:23:51 DEBUG] [run:224][39m Runtime strategies: hypothesis - default / rollbacks - default
[36m[2025-03-18 13:23:51 DEBUG] [caching:24][39m Building activity cache...
[36m[2025-03-18 13:23:51 DEBUG] [caching:35][39m Cached 3 activities
[36m[2025-03-18 13:23:51 DEBUG] [configuration:64][39m Loading configuration...
[36m[2025-03-18 13:23:51 DEBUG] [secret:79][39m Loading secrets...
[36m[2025-03-18 13:23:51 DEBUG] [secret:104][39m Done loading secrets
[36m[2025-03-18 13:23:51 DEBUG] [configuration:161][39m Loading dynamic configuration...
[32m[2025-03-18 13:23:51 INFO] [run:440][39m Running experiment: Privelege Scalation
[36m[2025-03-18 13:23:51 DEBUG] [__init__:67][39m Initializing controls
[32m[2025-03-18 13:23:51 INFO] [run:471][39m Steady-state strategy: default
[32m[2025-03-18 13:23:51 INFO] [run:477][39m Rollbacks strategy: default
[36m[2025-03-18 13:23:51 DEBUG] [__init__:472][39m No controls to apply on 'experiment'
[36m[2025-03-18 13:23:51 DEBUG] [run:654][39m Running steady-state hypothesis before the method
[32m[2025-03-18 13:23:51 INFO] [hypothesis:205][39m Steady state hypothesis: AWS GuardDuty detects the use of an instance profile credentials
[36m[2025-03-18 13:23:51 DEBUG] [__init__:472][39m No controls to apply on 'hypothesis'
[36m[2025-03-18 13:23:51 DEBUG] [__init__:472][39m No controls to apply on 'activity'
[32m[2025-03-18 13:23:51 INFO] [activity:232][39m Probe: GuarDuty-Findings
[36m[2025-03-18 13:23:51 DEBUG] [python:33][39m Activity 'GuarDuty-Findings' loaded from '/home/mmc/Descargas/devsecops-adversary-llm/SCE_Experiment/Runner/chaostk/lib/python3.12/site-packages/chaosaws/ec2/probes.py'
[36m[2025-03-18 13:23:51 DEBUG] [activity:260][39m   => succeeded with 'True'
[36m[2025-03-18 13:23:51 DEBUG] [__init__:472][39m No controls to apply on 'activity'
[36m[2025-03-18 13:23:51 DEBUG] [hypothesis:247][39m allowed tolerance is True
[32m[2025-03-18 13:23:51 INFO] [hypothesis:260][39m Steady state hypothesis is met!
[36m[2025-03-18 13:23:51 DEBUG] [__init__:472][39m No controls to apply on 'hypothesis'
[32m[2025-03-18 13:23:51 INFO] [run:778][39m Playing your experiment's method now...
[36m[2025-03-18 13:23:51 DEBUG] [__init__:472][39m No controls to apply on 'method'
[36m[2025-03-18 13:23:51 DEBUG] [__init__:472][39m No controls to apply on 'activity'
[32m[2025-03-18 13:23:51 INFO] [activity:232][39m Action: Creating_instance
[36m[2025-03-18 13:23:51 DEBUG] [python:33][39m Activity 'Creating_instance' loaded from '/home/mmc/Descargas/devsecops-adversary-llm/SCE_Experiment/Runner/chaostk/lib/python3.12/site-packages/chaosaws/ec2/actions.py'
[36m[2025-03-18 13:26:13 DEBUG] [__init__:472][39m No controls to apply on 'activity'
[36m[2025-03-18 13:26:13 DEBUG] [__init__:472][39m No controls to apply on 'method'
[33m[2025-03-18 13:26:13 WARNING] [run:556][39m Received a termination signal (Ctrl-C)...
[32m[2025-03-18 13:26:13 INFO] [run:598][39m Experiment ended with status: interrupted
[36m[2025-03-18 13:26:13 DEBUG] [__init__:472][39m No controls to apply on 'experiment'
[36m[2025-03-18 13:26:13 DEBUG] [__init__:106][39m Cleaning up controls
[36m[2025-03-18 13:26:13 DEBUG] [caching:42][39m Clearing activities cache
[36m[2025-03-18 13:26:36 DEBUG] [__init__:101][39m ###############################################################################
[36m[2025-03-18 13:26:36 DEBUG] [__init__:102][39m Running command 'run'
[36m[2025-03-18 13:26:36 DEBUG] [__init__:106][39m Using settings file '/home/mmc/.chaostoolkit/settings.yaml'
[36m[2025-03-18 13:26:36 DEBUG] [settings:31][39m The Chaos Toolkit settings file could not be found at '/home/mmc/.chaostoolkit/settings.yaml'.
[36m[2025-03-18 13:26:36 DEBUG] [__init__:472][39m No controls to apply on 'loader'
[36m[2025-03-18 13:26:36 DEBUG] [__init__:472][39m No controls to apply on 'loader'
[36m[2025-03-18 13:26:36 DEBUG] [caching:24][39m Building activity cache...
[36m[2025-03-18 13:26:36 DEBUG] [caching:35][39m Cached 3 activities
[32m[2025-03-18 13:26:36 INFO] [experiment:59][39m Validating the experiment's syntax
[36m[2025-03-18 13:26:36 DEBUG] [configuration:64][39m Loading configuration...
[36m[2025-03-18 13:26:36 DEBUG] [secret:79][39m Loading secrets...
[36m[2025-03-18 13:26:36 DEBUG] [secret:104][39m Done loading secrets
[32m[2025-03-18 13:26:36 INFO] [experiment:112][39m Experiment looks valid
[36m[2025-03-18 13:26:36 DEBUG] [caching:42][39m Clearing activities cache
[36m[2025-03-18 13:26:36 DEBUG] [run:224][39m Runtime strategies: hypothesis - default / rollbacks - default
[36m[2025-03-18 13:26:36 DEBUG] [caching:24][39m Building activity cache...
[36m[2025-03-18 13:26:36 DEBUG] [caching:35][39m Cached 3 activities
[36m[2025-03-18 13:26:36 DEBUG] [configuration:64][39m Loading configuration...
[36m[2025-03-18 13:26:36 DEBUG] [secret:79][39m Loading secrets...
[36m[2025-03-18 13:26:36 DEBUG] [secret:104][39m Done loading secrets
[36m[2025-03-18 13:26:36 DEBUG] [configuration:161][39m Loading dynamic configuration...
[32m[2025-03-18 13:26:36 INFO] [run:440][39m Running experiment: Privelege Scalation
[36m[2025-03-18 13:26:36 DEBUG] [__init__:67][39m Initializing controls
[32m[2025-03-18 13:26:36 INFO] [run:471][39m Steady-state strategy: default
[32m[2025-03-18 13:26:36 INFO] [run:477][39m Rollbacks strategy: default
[36m[2025-03-18 13:26:36 DEBUG] [__init__:472][39m No controls to apply on 'experiment'
[36m[2025-03-18 13:26:36 DEBUG] [run:654][39m Running steady-state hypothesis before the method
[32m[2025-03-18 13:26:36 INFO] [hypothesis:205][39m Steady state hypothesis: AWS GuardDuty detects the use of an instance profile credentials
[36m[2025-03-18 13:26:36 DEBUG] [__init__:472][39m No controls to apply on 'hypothesis'
[36m[2025-03-18 13:26:36 DEBUG] [__init__:472][39m No controls to apply on 'activity'
[32m[2025-03-18 13:26:36 INFO] [activity:232][39m Probe: GuarDuty-Findings
[36m[2025-03-18 13:26:36 DEBUG] [python:33][39m Activity 'GuarDuty-Findings' loaded from '/home/mmc/Descargas/devsecops-adversary-llm/SCE_Experiment/Runner/chaostk/lib/python3.12/site-packages/chaosaws/ec2/probes.py'
[36m[2025-03-18 13:26:36 DEBUG] [activity:260][39m   => succeeded with 'True'
[36m[2025-03-18 13:26:36 DEBUG] [__init__:472][39m No controls to apply on 'activity'
[36m[2025-03-18 13:26:36 DEBUG] [hypothesis:247][39m allowed tolerance is True
[32m[2025-03-18 13:26:36 INFO] [hypothesis:260][39m Steady state hypothesis is met!
[36m[2025-03-18 13:26:36 DEBUG] [__init__:472][39m No controls to apply on 'hypothesis'
[32m[2025-03-18 13:26:36 INFO] [run:778][39m Playing your experiment's method now...
[36m[2025-03-18 13:26:36 DEBUG] [__init__:472][39m No controls to apply on 'method'
[36m[2025-03-18 13:26:36 DEBUG] [__init__:472][39m No controls to apply on 'activity'
[32m[2025-03-18 13:26:36 INFO] [activity:232][39m Action: Creating_instance
[36m[2025-03-18 13:26:36 DEBUG] [python:33][39m Activity 'Creating_instance' loaded from '/home/mmc/Descargas/devsecops-adversary-llm/SCE_Experiment/Runner/chaostk/lib/python3.12/site-packages/chaosaws/ec2/actions.py'
[36m[2025-03-18 13:28:46 DEBUG] [activity:260][39m   => succeeded with 'True'
[36m[2025-03-18 13:28:46 DEBUG] [__init__:472][39m No controls to apply on 'activity'
[36m[2025-03-18 13:28:46 DEBUG] [__init__:472][39m No controls to apply on 'activity'
[32m[2025-03-18 13:28:46 INFO] [activity:232][39m Action: *******Extracting/Using credentials*******
[36m[2025-03-18 13:28:46 DEBUG] [python:33][39m Activity '*******Extracting/Using credentials*******' loaded from '/home/mmc/Descargas/devsecops-adversary-llm/SCE_Experiment/Runner/chaostk/lib/python3.12/site-packages/chaosaws/ec2/actions.py'
[36m[2025-03-18 13:28:46 DEBUG] [activity:317][39m Activity failed
    Traceback (most recent call last):
      File "/home/mmc/Descargas/devsecops-adversary-llm/SCE_Experiment/Runner/chaostk/lib/python3.12/site-packages/chaoslib/provider/python.py", line 56, in run_python_activity
        return func(**arguments)
               ^^^^^^^^^^^^^^^^^
      File "/home/mmc/Descargas/devsecops-adversary-llm/SCE_Experiment/Runner/chaostk/lib/python3.12/site-packages/chaosaws/ec2/actions.py", line 90, in extract_credentials_file
        new_keys = json.load(f)
                   ^^^^^^^^^^^^
      File "/usr/lib/python3.12/json/__init__.py", line 293, in load
        return loads(fp.read(),
               ^^^^^^^^^^^^^^^^
      File "/usr/lib/python3.12/json/__init__.py", line 346, in loads
        return _default_decoder.decode(s)
               ^^^^^^^^^^^^^^^^^^^^^^^^^^
      File "/usr/lib/python3.12/json/decoder.py", line 337, in decode
        obj, end = self.raw_decode(s, idx=_w(s, 0).end())
                   ^^^^^^^^^^^^^^^^^^^^^^^^^^^^^^^^^^^^^^
      File "/usr/lib/python3.12/json/decoder.py", line 355, in raw_decode
        raise JSONDecodeError("Expecting value", s, err.value) from None
    json.decoder.JSONDecodeError: Expecting value: line 1 column 1 (char 0)
    
    During handling of the above exception, another exception occurred:
    
    Traceback (most recent call last):
      File "/home/mmc/Descargas/devsecops-adversary-llm/SCE_Experiment/Runner/chaostk/lib/python3.12/site-packages/chaoslib/activity.py", line 310, in run_activity
        result = run_python_activity(activity, configuration, secrets)
                 ^^^^^^^^^^^^^^^^^^^^^^^^^^^^^^^^^^^^^^^^^^^^^^^^^^^^^
      File "/home/mmc/Descargas/devsecops-adversary-llm/SCE_Experiment/Runner/chaostk/lib/python3.12/site-packages/chaoslib/provider/python.py", line 58, in run_python_activity
        raise ActivityFailed(
      File "/home/mmc/Descargas/devsecops-adversary-llm/SCE_Experiment/Runner/chaostk/lib/python3.12/site-packages/chaoslib/provider/python.py", line 56, in run_python_activity
        return func(**arguments)
               ^^^^^^^^^^^^^^^^^
      File "/home/mmc/Descargas/devsecops-adversary-llm/SCE_Experiment/Runner/chaostk/lib/python3.12/site-packages/chaosaws/ec2/actions.py", line 90, in extract_credentials_file
        new_keys = json.load(f)
                   ^^^^^^^^^^^^
      File "/usr/lib/python3.12/json/__init__.py", line 293, in load
        return loads(fp.read(),
               ^^^^^^^^^^^^^^^^
      File "/usr/lib/python3.12/json/__init__.py", line 346, in loads
        return _default_decoder.decode(s)
               ^^^^^^^^^^^^^^^^^^^^^^^^^^
      File "/usr/lib/python3.12/json/decoder.py", line 337, in decode
        obj, end = self.raw_decode(s, idx=_w(s, 0).end())
                   ^^^^^^^^^^^^^^^^^^^^^^^^^^^^^^^^^^^^^^
      File "/usr/lib/python3.12/json/decoder.py", line 355, in raw_decode
        raise JSONDecodeError("Expecting value", s, err.value) from None
    chaoslib.exceptions.ActivityFailed: json.decoder.JSONDecodeError: Expecting value: line 1 column 1 (char 0)
[31m[2025-03-18 13:28:46 ERROR] [activity:268][39m   => failed: json.decoder.JSONDecodeError: Expecting value: line 1 column 1 (char 0)
[36m[2025-03-18 13:28:46 DEBUG] [__init__:472][39m No controls to apply on 'activity'
[36m[2025-03-18 13:28:46 DEBUG] [__init__:472][39m No controls to apply on 'method'
[36m[2025-03-18 13:28:46 DEBUG] [run:696][39m Running steady-state hypothesis after the method
[32m[2025-03-18 13:28:46 INFO] [hypothesis:205][39m Steady state hypothesis: AWS GuardDuty detects the use of an instance profile credentials
[36m[2025-03-18 13:28:46 DEBUG] [__init__:472][39m No controls to apply on 'hypothesis'
[36m[2025-03-18 13:28:46 DEBUG] [__init__:472][39m No controls to apply on 'activity'
[32m[2025-03-18 13:28:46 INFO] [activity:232][39m Probe: GuarDuty-Findings
[36m[2025-03-18 13:28:46 DEBUG] [python:33][39m Activity 'GuarDuty-Findings' loaded from '/home/mmc/Descargas/devsecops-adversary-llm/SCE_Experiment/Runner/chaostk/lib/python3.12/site-packages/chaosaws/ec2/probes.py'
[36m[2025-03-18 13:28:46 DEBUG] [activity:260][39m   => succeeded with 'True'
[36m[2025-03-18 13:28:46 DEBUG] [__init__:472][39m No controls to apply on 'activity'
[36m[2025-03-18 13:28:46 DEBUG] [hypothesis:247][39m allowed tolerance is True
[32m[2025-03-18 13:28:46 INFO] [hypothesis:260][39m Steady state hypothesis is met!
[36m[2025-03-18 13:28:46 DEBUG] [__init__:472][39m No controls to apply on 'hypothesis'
[32m[2025-03-18 13:28:46 INFO] [run:1072][39m Let's rollback...
[36m[2025-03-18 13:28:46 DEBUG] [__init__:472][39m No controls to apply on 'rollback'
[32m[2025-03-18 13:28:46 INFO] [rollback:33][39m No declared rollbacks, let's move on.
[36m[2025-03-18 13:28:46 DEBUG] [__init__:472][39m No controls to apply on 'rollback'
[32m[2025-03-18 13:28:46 INFO] [run:598][39m Experiment ended with status: completed
[36m[2025-03-18 13:28:46 DEBUG] [__init__:472][39m No controls to apply on 'experiment'
[36m[2025-03-18 13:28:46 DEBUG] [__init__:106][39m Cleaning up controls
[36m[2025-03-18 13:28:46 DEBUG] [caching:42][39m Clearing activities cache
[36m[2025-03-18 13:30:00 DEBUG] [__init__:101][39m ###############################################################################
[36m[2025-03-18 13:30:00 DEBUG] [__init__:102][39m Running command 'run'
[36m[2025-03-18 13:30:00 DEBUG] [__init__:106][39m Using settings file '/home/mmc/.chaostoolkit/settings.yaml'
[36m[2025-03-18 13:30:00 DEBUG] [settings:31][39m The Chaos Toolkit settings file could not be found at '/home/mmc/.chaostoolkit/settings.yaml'.
[36m[2025-03-18 13:30:00 DEBUG] [__init__:472][39m No controls to apply on 'loader'
[36m[2025-03-18 13:30:00 DEBUG] [__init__:472][39m No controls to apply on 'loader'
[36m[2025-03-18 13:30:00 DEBUG] [caching:24][39m Building activity cache...
[36m[2025-03-18 13:30:00 DEBUG] [caching:35][39m Cached 3 activities
[32m[2025-03-18 13:30:00 INFO] [experiment:59][39m Validating the experiment's syntax
[36m[2025-03-18 13:30:00 DEBUG] [configuration:64][39m Loading configuration...
[36m[2025-03-18 13:30:00 DEBUG] [secret:79][39m Loading secrets...
[36m[2025-03-18 13:30:00 DEBUG] [secret:104][39m Done loading secrets
[32m[2025-03-18 13:30:01 INFO] [experiment:112][39m Experiment looks valid
[36m[2025-03-18 13:30:01 DEBUG] [caching:42][39m Clearing activities cache
[36m[2025-03-18 13:30:01 DEBUG] [run:224][39m Runtime strategies: hypothesis - default / rollbacks - default
[36m[2025-03-18 13:30:01 DEBUG] [caching:24][39m Building activity cache...
[36m[2025-03-18 13:30:01 DEBUG] [caching:35][39m Cached 3 activities
[36m[2025-03-18 13:30:01 DEBUG] [configuration:64][39m Loading configuration...
[36m[2025-03-18 13:30:01 DEBUG] [secret:79][39m Loading secrets...
[36m[2025-03-18 13:30:01 DEBUG] [secret:104][39m Done loading secrets
[36m[2025-03-18 13:30:01 DEBUG] [configuration:161][39m Loading dynamic configuration...
[32m[2025-03-18 13:30:01 INFO] [run:440][39m Running experiment: Privelege Scalation
[36m[2025-03-18 13:30:01 DEBUG] [__init__:67][39m Initializing controls
[32m[2025-03-18 13:30:01 INFO] [run:471][39m Steady-state strategy: default
[32m[2025-03-18 13:30:01 INFO] [run:477][39m Rollbacks strategy: default
[36m[2025-03-18 13:30:01 DEBUG] [__init__:472][39m No controls to apply on 'experiment'
[36m[2025-03-18 13:30:01 DEBUG] [run:654][39m Running steady-state hypothesis before the method
[32m[2025-03-18 13:30:01 INFO] [hypothesis:205][39m Steady state hypothesis: AWS GuardDuty detects the use of an instance profile credentials
[36m[2025-03-18 13:30:01 DEBUG] [__init__:472][39m No controls to apply on 'hypothesis'
[36m[2025-03-18 13:30:01 DEBUG] [__init__:472][39m No controls to apply on 'activity'
[32m[2025-03-18 13:30:01 INFO] [activity:232][39m Probe: GuarDuty-Findings
[36m[2025-03-18 13:30:01 DEBUG] [python:33][39m Activity 'GuarDuty-Findings' loaded from '/home/mmc/Descargas/devsecops-adversary-llm/SCE_Experiment/Runner/chaostk/lib/python3.12/site-packages/chaosaws/ec2/probes.py'
[36m[2025-03-18 13:30:01 DEBUG] [activity:260][39m   => succeeded with 'True'
[36m[2025-03-18 13:30:01 DEBUG] [__init__:472][39m No controls to apply on 'activity'
[36m[2025-03-18 13:30:01 DEBUG] [hypothesis:247][39m allowed tolerance is True
[32m[2025-03-18 13:30:01 INFO] [hypothesis:260][39m Steady state hypothesis is met!
[36m[2025-03-18 13:30:01 DEBUG] [__init__:472][39m No controls to apply on 'hypothesis'
[32m[2025-03-18 13:30:01 INFO] [run:778][39m Playing your experiment's method now...
[36m[2025-03-18 13:30:01 DEBUG] [__init__:472][39m No controls to apply on 'method'
[36m[2025-03-18 13:30:01 DEBUG] [__init__:472][39m No controls to apply on 'activity'
[32m[2025-03-18 13:30:01 INFO] [activity:232][39m Action: Creating_instance
[36m[2025-03-18 13:30:01 DEBUG] [python:33][39m Activity 'Creating_instance' loaded from '/home/mmc/Descargas/devsecops-adversary-llm/SCE_Experiment/Runner/chaostk/lib/python3.12/site-packages/chaosaws/ec2/actions.py'
[36m[2025-03-18 13:30:17 DEBUG] [__init__:472][39m No controls to apply on 'activity'
[36m[2025-03-18 13:30:17 DEBUG] [__init__:472][39m No controls to apply on 'method'
[33m[2025-03-18 13:30:17 WARNING] [run:556][39m Received a termination signal (Ctrl-C)...
[32m[2025-03-18 13:30:17 INFO] [run:598][39m Experiment ended with status: interrupted
[36m[2025-03-18 13:30:17 DEBUG] [__init__:472][39m No controls to apply on 'experiment'
[36m[2025-03-18 13:30:17 DEBUG] [__init__:106][39m Cleaning up controls
[36m[2025-03-18 13:30:17 DEBUG] [caching:42][39m Clearing activities cache
[36m[2025-03-18 13:30:21 DEBUG] [__init__:101][39m ###############################################################################
[36m[2025-03-18 13:30:21 DEBUG] [__init__:102][39m Running command 'run'
[36m[2025-03-18 13:30:21 DEBUG] [__init__:106][39m Using settings file '/home/mmc/.chaostoolkit/settings.yaml'
[36m[2025-03-18 13:30:21 DEBUG] [settings:31][39m The Chaos Toolkit settings file could not be found at '/home/mmc/.chaostoolkit/settings.yaml'.
[36m[2025-03-18 13:30:21 DEBUG] [__init__:472][39m No controls to apply on 'loader'
[36m[2025-03-18 13:30:21 DEBUG] [__init__:472][39m No controls to apply on 'loader'
[36m[2025-03-18 13:30:21 DEBUG] [caching:24][39m Building activity cache...
[36m[2025-03-18 13:30:21 DEBUG] [caching:35][39m Cached 3 activities
[32m[2025-03-18 13:30:21 INFO] [experiment:59][39m Validating the experiment's syntax
[36m[2025-03-18 13:30:21 DEBUG] [configuration:64][39m Loading configuration...
[36m[2025-03-18 13:30:21 DEBUG] [secret:79][39m Loading secrets...
[36m[2025-03-18 13:30:21 DEBUG] [secret:104][39m Done loading secrets
[32m[2025-03-18 13:30:21 INFO] [experiment:112][39m Experiment looks valid
[36m[2025-03-18 13:30:21 DEBUG] [caching:42][39m Clearing activities cache
[36m[2025-03-18 13:30:21 DEBUG] [run:224][39m Runtime strategies: hypothesis - default / rollbacks - default
[36m[2025-03-18 13:30:21 DEBUG] [caching:24][39m Building activity cache...
[36m[2025-03-18 13:30:21 DEBUG] [caching:35][39m Cached 3 activities
[36m[2025-03-18 13:30:21 DEBUG] [configuration:64][39m Loading configuration...
[36m[2025-03-18 13:30:21 DEBUG] [secret:79][39m Loading secrets...
[36m[2025-03-18 13:30:21 DEBUG] [secret:104][39m Done loading secrets
[36m[2025-03-18 13:30:21 DEBUG] [configuration:161][39m Loading dynamic configuration...
[32m[2025-03-18 13:30:21 INFO] [run:440][39m Running experiment: Privelege Scalation
[36m[2025-03-18 13:30:21 DEBUG] [__init__:67][39m Initializing controls
[32m[2025-03-18 13:30:21 INFO] [run:471][39m Steady-state strategy: default
[32m[2025-03-18 13:30:21 INFO] [run:477][39m Rollbacks strategy: default
[36m[2025-03-18 13:30:21 DEBUG] [__init__:472][39m No controls to apply on 'experiment'
[36m[2025-03-18 13:30:21 DEBUG] [run:654][39m Running steady-state hypothesis before the method
[32m[2025-03-18 13:30:21 INFO] [hypothesis:205][39m Steady state hypothesis: AWS GuardDuty detects the use of an instance profile credentials
[36m[2025-03-18 13:30:21 DEBUG] [__init__:472][39m No controls to apply on 'hypothesis'
[36m[2025-03-18 13:30:21 DEBUG] [__init__:472][39m No controls to apply on 'activity'
[32m[2025-03-18 13:30:21 INFO] [activity:232][39m Probe: GuarDuty-Findings
[36m[2025-03-18 13:30:21 DEBUG] [python:33][39m Activity 'GuarDuty-Findings' loaded from '/home/mmc/Descargas/devsecops-adversary-llm/SCE_Experiment/Runner/chaostk/lib/python3.12/site-packages/chaosaws/ec2/probes.py'
[36m[2025-03-18 13:30:21 DEBUG] [activity:260][39m   => succeeded with 'True'
[36m[2025-03-18 13:30:21 DEBUG] [__init__:472][39m No controls to apply on 'activity'
[36m[2025-03-18 13:30:21 DEBUG] [hypothesis:247][39m allowed tolerance is True
[32m[2025-03-18 13:30:21 INFO] [hypothesis:260][39m Steady state hypothesis is met!
[36m[2025-03-18 13:30:21 DEBUG] [__init__:472][39m No controls to apply on 'hypothesis'
[32m[2025-03-18 13:30:21 INFO] [run:778][39m Playing your experiment's method now...
[36m[2025-03-18 13:30:21 DEBUG] [__init__:472][39m No controls to apply on 'method'
[36m[2025-03-18 13:30:21 DEBUG] [__init__:472][39m No controls to apply on 'activity'
[32m[2025-03-18 13:30:21 INFO] [activity:232][39m Action: Creating_instance
[36m[2025-03-18 13:30:21 DEBUG] [python:33][39m Activity 'Creating_instance' loaded from '/home/mmc/Descargas/devsecops-adversary-llm/SCE_Experiment/Runner/chaostk/lib/python3.12/site-packages/chaosaws/ec2/actions.py'
[36m[2025-03-18 13:30:56 DEBUG] [__init__:472][39m No controls to apply on 'activity'
[36m[2025-03-18 13:30:56 DEBUG] [__init__:472][39m No controls to apply on 'method'
[33m[2025-03-18 13:30:56 WARNING] [run:556][39m Received a termination signal (Ctrl-C)...
[32m[2025-03-18 13:30:56 INFO] [run:598][39m Experiment ended with status: interrupted
[36m[2025-03-18 13:30:56 DEBUG] [__init__:472][39m No controls to apply on 'experiment'
[36m[2025-03-18 13:30:56 DEBUG] [__init__:106][39m Cleaning up controls
[36m[2025-03-18 13:30:56 DEBUG] [caching:42][39m Clearing activities cache
[36m[2025-03-18 13:31:20 DEBUG] [__init__:101][39m ###############################################################################
[36m[2025-03-18 13:31:20 DEBUG] [__init__:102][39m Running command 'run'
[36m[2025-03-18 13:31:20 DEBUG] [__init__:106][39m Using settings file '/home/mmc/.chaostoolkit/settings.yaml'
[36m[2025-03-18 13:31:20 DEBUG] [settings:31][39m The Chaos Toolkit settings file could not be found at '/home/mmc/.chaostoolkit/settings.yaml'.
[36m[2025-03-18 13:31:20 DEBUG] [__init__:472][39m No controls to apply on 'loader'
[36m[2025-03-18 13:31:20 DEBUG] [__init__:472][39m No controls to apply on 'loader'
[36m[2025-03-18 13:31:20 DEBUG] [caching:24][39m Building activity cache...
[36m[2025-03-18 13:31:20 DEBUG] [caching:35][39m Cached 3 activities
[32m[2025-03-18 13:31:20 INFO] [experiment:59][39m Validating the experiment's syntax
[36m[2025-03-18 13:31:20 DEBUG] [configuration:64][39m Loading configuration...
[36m[2025-03-18 13:31:20 DEBUG] [secret:79][39m Loading secrets...
[36m[2025-03-18 13:31:20 DEBUG] [secret:104][39m Done loading secrets
[32m[2025-03-18 13:31:20 INFO] [experiment:112][39m Experiment looks valid
[36m[2025-03-18 13:31:20 DEBUG] [caching:42][39m Clearing activities cache
[36m[2025-03-18 13:31:20 DEBUG] [run:224][39m Runtime strategies: hypothesis - default / rollbacks - default
[36m[2025-03-18 13:31:20 DEBUG] [caching:24][39m Building activity cache...
[36m[2025-03-18 13:31:20 DEBUG] [caching:35][39m Cached 3 activities
[36m[2025-03-18 13:31:20 DEBUG] [configuration:64][39m Loading configuration...
[36m[2025-03-18 13:31:20 DEBUG] [secret:79][39m Loading secrets...
[36m[2025-03-18 13:31:20 DEBUG] [secret:104][39m Done loading secrets
[36m[2025-03-18 13:31:20 DEBUG] [configuration:161][39m Loading dynamic configuration...
[32m[2025-03-18 13:31:20 INFO] [run:440][39m Running experiment: Privelege Scalation
[36m[2025-03-18 13:31:20 DEBUG] [__init__:67][39m Initializing controls
[32m[2025-03-18 13:31:20 INFO] [run:471][39m Steady-state strategy: default
[32m[2025-03-18 13:31:20 INFO] [run:477][39m Rollbacks strategy: default
[36m[2025-03-18 13:31:20 DEBUG] [__init__:472][39m No controls to apply on 'experiment'
[36m[2025-03-18 13:31:20 DEBUG] [run:654][39m Running steady-state hypothesis before the method
[32m[2025-03-18 13:31:20 INFO] [hypothesis:205][39m Steady state hypothesis: AWS GuardDuty detects the use of an instance profile credentials
[36m[2025-03-18 13:31:20 DEBUG] [__init__:472][39m No controls to apply on 'hypothesis'
[36m[2025-03-18 13:31:20 DEBUG] [__init__:472][39m No controls to apply on 'activity'
[32m[2025-03-18 13:31:20 INFO] [activity:232][39m Probe: GuarDuty-Findings
[36m[2025-03-18 13:31:20 DEBUG] [python:33][39m Activity 'GuarDuty-Findings' loaded from '/home/mmc/Descargas/devsecops-adversary-llm/SCE_Experiment/Runner/chaostk/lib/python3.12/site-packages/chaosaws/ec2/probes.py'
[36m[2025-03-18 13:31:20 DEBUG] [activity:260][39m   => succeeded with 'True'
[36m[2025-03-18 13:31:20 DEBUG] [__init__:472][39m No controls to apply on 'activity'
[36m[2025-03-18 13:31:20 DEBUG] [hypothesis:247][39m allowed tolerance is True
[32m[2025-03-18 13:31:20 INFO] [hypothesis:260][39m Steady state hypothesis is met!
[36m[2025-03-18 13:31:20 DEBUG] [__init__:472][39m No controls to apply on 'hypothesis'
[32m[2025-03-18 13:31:20 INFO] [run:778][39m Playing your experiment's method now...
[36m[2025-03-18 13:31:20 DEBUG] [__init__:472][39m No controls to apply on 'method'
[36m[2025-03-18 13:31:20 DEBUG] [__init__:472][39m No controls to apply on 'activity'
[32m[2025-03-18 13:31:20 INFO] [activity:232][39m Action: Creating_instance
[36m[2025-03-18 13:31:20 DEBUG] [python:33][39m Activity 'Creating_instance' loaded from '/home/mmc/Descargas/devsecops-adversary-llm/SCE_Experiment/Runner/chaostk/lib/python3.12/site-packages/chaosaws/ec2/actions.py'
[36m[2025-03-18 13:31:22 DEBUG] [__init__:472][39m No controls to apply on 'activity'
[36m[2025-03-18 13:31:22 DEBUG] [__init__:472][39m No controls to apply on 'method'
[33m[2025-03-18 13:31:22 WARNING] [run:556][39m Received a termination signal (Ctrl-C)...
[32m[2025-03-18 13:31:22 INFO] [run:598][39m Experiment ended with status: interrupted
[36m[2025-03-18 13:31:22 DEBUG] [__init__:472][39m No controls to apply on 'experiment'
[36m[2025-03-18 13:31:22 DEBUG] [__init__:106][39m Cleaning up controls
[36m[2025-03-18 13:31:22 DEBUG] [caching:42][39m Clearing activities cache
[36m[2025-03-18 13:31:47 DEBUG] [__init__:101][39m ###############################################################################
[36m[2025-03-18 13:31:47 DEBUG] [__init__:102][39m Running command 'run'
[36m[2025-03-18 13:31:47 DEBUG] [__init__:106][39m Using settings file '/home/mmc/.chaostoolkit/settings.yaml'
[36m[2025-03-18 13:31:47 DEBUG] [settings:31][39m The Chaos Toolkit settings file could not be found at '/home/mmc/.chaostoolkit/settings.yaml'.
[36m[2025-03-18 13:31:47 DEBUG] [__init__:472][39m No controls to apply on 'loader'
[36m[2025-03-18 13:31:47 DEBUG] [__init__:472][39m No controls to apply on 'loader'
[36m[2025-03-18 13:31:47 DEBUG] [caching:24][39m Building activity cache...
[36m[2025-03-18 13:31:47 DEBUG] [caching:35][39m Cached 3 activities
[32m[2025-03-18 13:31:47 INFO] [experiment:59][39m Validating the experiment's syntax
[36m[2025-03-18 13:31:47 DEBUG] [configuration:64][39m Loading configuration...
[36m[2025-03-18 13:31:47 DEBUG] [secret:79][39m Loading secrets...
[36m[2025-03-18 13:31:47 DEBUG] [secret:104][39m Done loading secrets
[32m[2025-03-18 13:31:47 INFO] [experiment:112][39m Experiment looks valid
[36m[2025-03-18 13:31:47 DEBUG] [caching:42][39m Clearing activities cache
[36m[2025-03-18 13:31:47 DEBUG] [run:224][39m Runtime strategies: hypothesis - default / rollbacks - default
[36m[2025-03-18 13:31:47 DEBUG] [caching:24][39m Building activity cache...
[36m[2025-03-18 13:31:47 DEBUG] [caching:35][39m Cached 3 activities
[36m[2025-03-18 13:31:47 DEBUG] [configuration:64][39m Loading configuration...
[36m[2025-03-18 13:31:47 DEBUG] [secret:79][39m Loading secrets...
[36m[2025-03-18 13:31:47 DEBUG] [secret:104][39m Done loading secrets
[36m[2025-03-18 13:31:47 DEBUG] [configuration:161][39m Loading dynamic configuration...
[32m[2025-03-18 13:31:47 INFO] [run:440][39m Running experiment: Privelege Scalation
[36m[2025-03-18 13:31:47 DEBUG] [__init__:67][39m Initializing controls
[32m[2025-03-18 13:31:47 INFO] [run:471][39m Steady-state strategy: default
[32m[2025-03-18 13:31:47 INFO] [run:477][39m Rollbacks strategy: default
[36m[2025-03-18 13:31:47 DEBUG] [__init__:472][39m No controls to apply on 'experiment'
[36m[2025-03-18 13:31:47 DEBUG] [run:654][39m Running steady-state hypothesis before the method
[32m[2025-03-18 13:31:47 INFO] [hypothesis:205][39m Steady state hypothesis: AWS GuardDuty detects the use of an instance profile credentials
[36m[2025-03-18 13:31:47 DEBUG] [__init__:472][39m No controls to apply on 'hypothesis'
[36m[2025-03-18 13:31:47 DEBUG] [__init__:472][39m No controls to apply on 'activity'
[32m[2025-03-18 13:31:47 INFO] [activity:232][39m Probe: GuarDuty-Findings
[36m[2025-03-18 13:31:47 DEBUG] [python:33][39m Activity 'GuarDuty-Findings' loaded from '/home/mmc/Descargas/devsecops-adversary-llm/SCE_Experiment/Runner/chaostk/lib/python3.12/site-packages/chaosaws/ec2/probes.py'
[36m[2025-03-18 13:31:47 DEBUG] [activity:260][39m   => succeeded with 'True'
[36m[2025-03-18 13:31:47 DEBUG] [__init__:472][39m No controls to apply on 'activity'
[36m[2025-03-18 13:31:47 DEBUG] [hypothesis:247][39m allowed tolerance is True
[32m[2025-03-18 13:31:47 INFO] [hypothesis:260][39m Steady state hypothesis is met!
[36m[2025-03-18 13:31:47 DEBUG] [__init__:472][39m No controls to apply on 'hypothesis'
[32m[2025-03-18 13:31:47 INFO] [run:778][39m Playing your experiment's method now...
[36m[2025-03-18 13:31:47 DEBUG] [__init__:472][39m No controls to apply on 'method'
[36m[2025-03-18 13:31:47 DEBUG] [__init__:472][39m No controls to apply on 'activity'
[32m[2025-03-18 13:31:47 INFO] [activity:232][39m Action: Creating_instance
[36m[2025-03-18 13:31:47 DEBUG] [python:33][39m Activity 'Creating_instance' loaded from '/home/mmc/Descargas/devsecops-adversary-llm/SCE_Experiment/Runner/chaostk/lib/python3.12/site-packages/chaosaws/ec2/actions.py'
[36m[2025-03-18 13:31:49 DEBUG] [activity:260][39m   => succeeded with 'False'
[36m[2025-03-18 13:31:49 DEBUG] [__init__:472][39m No controls to apply on 'activity'
[36m[2025-03-18 13:31:49 DEBUG] [__init__:472][39m No controls to apply on 'activity'
[32m[2025-03-18 13:31:49 INFO] [activity:232][39m Action: *******Extracting/Using credentials*******
[36m[2025-03-18 13:31:49 DEBUG] [python:33][39m Activity '*******Extracting/Using credentials*******' loaded from '/home/mmc/Descargas/devsecops-adversary-llm/SCE_Experiment/Runner/chaostk/lib/python3.12/site-packages/chaosaws/ec2/actions.py'
[36m[2025-03-18 13:31:49 DEBUG] [activity:317][39m Activity failed
    Traceback (most recent call last):
      File "/home/mmc/Descargas/devsecops-adversary-llm/SCE_Experiment/Runner/chaostk/lib/python3.12/site-packages/chaoslib/provider/python.py", line 56, in run_python_activity
        return func(**arguments)
               ^^^^^^^^^^^^^^^^^
      File "/home/mmc/Descargas/devsecops-adversary-llm/SCE_Experiment/Runner/chaostk/lib/python3.12/site-packages/chaosaws/ec2/actions.py", line 90, in extract_credentials_file
        new_keys = json.load(f)
                   ^^^^^^^^^^^^
      File "/usr/lib/python3.12/json/__init__.py", line 293, in load
        return loads(fp.read(),
               ^^^^^^^^^^^^^^^^
      File "/usr/lib/python3.12/json/__init__.py", line 346, in loads
        return _default_decoder.decode(s)
               ^^^^^^^^^^^^^^^^^^^^^^^^^^
      File "/usr/lib/python3.12/json/decoder.py", line 337, in decode
        obj, end = self.raw_decode(s, idx=_w(s, 0).end())
                   ^^^^^^^^^^^^^^^^^^^^^^^^^^^^^^^^^^^^^^
      File "/usr/lib/python3.12/json/decoder.py", line 355, in raw_decode
        raise JSONDecodeError("Expecting value", s, err.value) from None
    json.decoder.JSONDecodeError: Expecting value: line 1 column 1 (char 0)
    
    During handling of the above exception, another exception occurred:
    
    Traceback (most recent call last):
      File "/home/mmc/Descargas/devsecops-adversary-llm/SCE_Experiment/Runner/chaostk/lib/python3.12/site-packages/chaoslib/activity.py", line 310, in run_activity
        result = run_python_activity(activity, configuration, secrets)
                 ^^^^^^^^^^^^^^^^^^^^^^^^^^^^^^^^^^^^^^^^^^^^^^^^^^^^^
      File "/home/mmc/Descargas/devsecops-adversary-llm/SCE_Experiment/Runner/chaostk/lib/python3.12/site-packages/chaoslib/provider/python.py", line 58, in run_python_activity
        raise ActivityFailed(
      File "/home/mmc/Descargas/devsecops-adversary-llm/SCE_Experiment/Runner/chaostk/lib/python3.12/site-packages/chaoslib/provider/python.py", line 56, in run_python_activity
        return func(**arguments)
               ^^^^^^^^^^^^^^^^^
      File "/home/mmc/Descargas/devsecops-adversary-llm/SCE_Experiment/Runner/chaostk/lib/python3.12/site-packages/chaosaws/ec2/actions.py", line 90, in extract_credentials_file
        new_keys = json.load(f)
                   ^^^^^^^^^^^^
      File "/usr/lib/python3.12/json/__init__.py", line 293, in load
        return loads(fp.read(),
               ^^^^^^^^^^^^^^^^
      File "/usr/lib/python3.12/json/__init__.py", line 346, in loads
        return _default_decoder.decode(s)
               ^^^^^^^^^^^^^^^^^^^^^^^^^^
      File "/usr/lib/python3.12/json/decoder.py", line 337, in decode
        obj, end = self.raw_decode(s, idx=_w(s, 0).end())
                   ^^^^^^^^^^^^^^^^^^^^^^^^^^^^^^^^^^^^^^
      File "/usr/lib/python3.12/json/decoder.py", line 355, in raw_decode
        raise JSONDecodeError("Expecting value", s, err.value) from None
    chaoslib.exceptions.ActivityFailed: json.decoder.JSONDecodeError: Expecting value: line 1 column 1 (char 0)
[31m[2025-03-18 13:31:49 ERROR] [activity:268][39m   => failed: json.decoder.JSONDecodeError: Expecting value: line 1 column 1 (char 0)
[36m[2025-03-18 13:31:49 DEBUG] [__init__:472][39m No controls to apply on 'activity'
[36m[2025-03-18 13:31:49 DEBUG] [__init__:472][39m No controls to apply on 'method'
[36m[2025-03-18 13:31:49 DEBUG] [run:696][39m Running steady-state hypothesis after the method
[32m[2025-03-18 13:31:49 INFO] [hypothesis:205][39m Steady state hypothesis: AWS GuardDuty detects the use of an instance profile credentials
[36m[2025-03-18 13:31:49 DEBUG] [__init__:472][39m No controls to apply on 'hypothesis'
[36m[2025-03-18 13:31:49 DEBUG] [__init__:472][39m No controls to apply on 'activity'
[32m[2025-03-18 13:31:49 INFO] [activity:232][39m Probe: GuarDuty-Findings
[36m[2025-03-18 13:31:49 DEBUG] [python:33][39m Activity 'GuarDuty-Findings' loaded from '/home/mmc/Descargas/devsecops-adversary-llm/SCE_Experiment/Runner/chaostk/lib/python3.12/site-packages/chaosaws/ec2/probes.py'
[36m[2025-03-18 13:31:49 DEBUG] [activity:260][39m   => succeeded with 'True'
[36m[2025-03-18 13:31:49 DEBUG] [__init__:472][39m No controls to apply on 'activity'
[36m[2025-03-18 13:31:49 DEBUG] [hypothesis:247][39m allowed tolerance is True
[32m[2025-03-18 13:31:49 INFO] [hypothesis:260][39m Steady state hypothesis is met!
[36m[2025-03-18 13:31:49 DEBUG] [__init__:472][39m No controls to apply on 'hypothesis'
[32m[2025-03-18 13:31:49 INFO] [run:1072][39m Let's rollback...
[36m[2025-03-18 13:31:49 DEBUG] [__init__:472][39m No controls to apply on 'rollback'
[32m[2025-03-18 13:31:49 INFO] [rollback:33][39m No declared rollbacks, let's move on.
[36m[2025-03-18 13:31:49 DEBUG] [__init__:472][39m No controls to apply on 'rollback'
[32m[2025-03-18 13:31:49 INFO] [run:598][39m Experiment ended with status: completed
[36m[2025-03-18 13:31:49 DEBUG] [__init__:472][39m No controls to apply on 'experiment'
[36m[2025-03-18 13:31:49 DEBUG] [__init__:106][39m Cleaning up controls
[36m[2025-03-18 13:31:49 DEBUG] [caching:42][39m Clearing activities cache
[36m[2025-03-18 13:31:53 DEBUG] [__init__:101][39m ###############################################################################
[36m[2025-03-18 13:31:53 DEBUG] [__init__:102][39m Running command 'run'
[36m[2025-03-18 13:31:53 DEBUG] [__init__:106][39m Using settings file '/home/mmc/.chaostoolkit/settings.yaml'
[36m[2025-03-18 13:31:53 DEBUG] [settings:31][39m The Chaos Toolkit settings file could not be found at '/home/mmc/.chaostoolkit/settings.yaml'.
[36m[2025-03-18 13:31:53 DEBUG] [__init__:472][39m No controls to apply on 'loader'
[36m[2025-03-18 13:31:53 DEBUG] [__init__:472][39m No controls to apply on 'loader'
[36m[2025-03-18 13:31:53 DEBUG] [caching:24][39m Building activity cache...
[36m[2025-03-18 13:31:53 DEBUG] [caching:35][39m Cached 3 activities
[32m[2025-03-18 13:31:53 INFO] [experiment:59][39m Validating the experiment's syntax
[36m[2025-03-18 13:31:53 DEBUG] [configuration:64][39m Loading configuration...
[36m[2025-03-18 13:31:53 DEBUG] [secret:79][39m Loading secrets...
[36m[2025-03-18 13:31:53 DEBUG] [secret:104][39m Done loading secrets
[32m[2025-03-18 13:31:53 INFO] [experiment:112][39m Experiment looks valid
[36m[2025-03-18 13:31:53 DEBUG] [caching:42][39m Clearing activities cache
[36m[2025-03-18 13:31:53 DEBUG] [run:224][39m Runtime strategies: hypothesis - default / rollbacks - default
[36m[2025-03-18 13:31:53 DEBUG] [caching:24][39m Building activity cache...
[36m[2025-03-18 13:31:53 DEBUG] [caching:35][39m Cached 3 activities
[36m[2025-03-18 13:31:53 DEBUG] [configuration:64][39m Loading configuration...
[36m[2025-03-18 13:31:53 DEBUG] [secret:79][39m Loading secrets...
[36m[2025-03-18 13:31:53 DEBUG] [secret:104][39m Done loading secrets
[36m[2025-03-18 13:31:53 DEBUG] [configuration:161][39m Loading dynamic configuration...
[32m[2025-03-18 13:31:53 INFO] [run:440][39m Running experiment: Privelege Scalation
[36m[2025-03-18 13:31:53 DEBUG] [__init__:67][39m Initializing controls
[32m[2025-03-18 13:31:53 INFO] [run:471][39m Steady-state strategy: default
[32m[2025-03-18 13:31:53 INFO] [run:477][39m Rollbacks strategy: default
[36m[2025-03-18 13:31:53 DEBUG] [__init__:472][39m No controls to apply on 'experiment'
[36m[2025-03-18 13:31:53 DEBUG] [run:654][39m Running steady-state hypothesis before the method
[32m[2025-03-18 13:31:53 INFO] [hypothesis:205][39m Steady state hypothesis: AWS GuardDuty detects the use of an instance profile credentials
[36m[2025-03-18 13:31:53 DEBUG] [__init__:472][39m No controls to apply on 'hypothesis'
[36m[2025-03-18 13:31:53 DEBUG] [__init__:472][39m No controls to apply on 'activity'
[32m[2025-03-18 13:31:53 INFO] [activity:232][39m Probe: GuarDuty-Findings
[36m[2025-03-18 13:31:53 DEBUG] [python:33][39m Activity 'GuarDuty-Findings' loaded from '/home/mmc/Descargas/devsecops-adversary-llm/SCE_Experiment/Runner/chaostk/lib/python3.12/site-packages/chaosaws/ec2/probes.py'
[36m[2025-03-18 13:31:53 DEBUG] [activity:260][39m   => succeeded with 'True'
[36m[2025-03-18 13:31:53 DEBUG] [__init__:472][39m No controls to apply on 'activity'
[36m[2025-03-18 13:31:53 DEBUG] [hypothesis:247][39m allowed tolerance is True
[32m[2025-03-18 13:31:53 INFO] [hypothesis:260][39m Steady state hypothesis is met!
[36m[2025-03-18 13:31:53 DEBUG] [__init__:472][39m No controls to apply on 'hypothesis'
[32m[2025-03-18 13:31:53 INFO] [run:778][39m Playing your experiment's method now...
[36m[2025-03-18 13:31:53 DEBUG] [__init__:472][39m No controls to apply on 'method'
[36m[2025-03-18 13:31:53 DEBUG] [__init__:472][39m No controls to apply on 'activity'
[32m[2025-03-18 13:31:53 INFO] [activity:232][39m Action: Creating_instance
[36m[2025-03-18 13:31:53 DEBUG] [python:33][39m Activity 'Creating_instance' loaded from '/home/mmc/Descargas/devsecops-adversary-llm/SCE_Experiment/Runner/chaostk/lib/python3.12/site-packages/chaosaws/ec2/actions.py'
[36m[2025-03-18 13:31:55 DEBUG] [__init__:472][39m No controls to apply on 'activity'
[36m[2025-03-18 13:31:55 DEBUG] [__init__:472][39m No controls to apply on 'method'
[33m[2025-03-18 13:31:55 WARNING] [run:556][39m Received a termination signal (Ctrl-C)...
[32m[2025-03-18 13:31:55 INFO] [run:598][39m Experiment ended with status: interrupted
[36m[2025-03-18 13:31:55 DEBUG] [__init__:472][39m No controls to apply on 'experiment'
[36m[2025-03-18 13:31:55 DEBUG] [__init__:106][39m Cleaning up controls
[36m[2025-03-18 13:31:55 DEBUG] [caching:42][39m Clearing activities cache
[36m[2025-03-18 13:35:08 DEBUG] [__init__:101][39m ###############################################################################
[36m[2025-03-18 13:35:08 DEBUG] [__init__:102][39m Running command 'run'
[36m[2025-03-18 13:35:08 DEBUG] [__init__:106][39m Using settings file '/home/mmc/.chaostoolkit/settings.yaml'
[36m[2025-03-18 13:35:08 DEBUG] [settings:31][39m The Chaos Toolkit settings file could not be found at '/home/mmc/.chaostoolkit/settings.yaml'.
[36m[2025-03-18 13:35:08 DEBUG] [__init__:472][39m No controls to apply on 'loader'
[36m[2025-03-18 13:35:08 DEBUG] [__init__:472][39m No controls to apply on 'loader'
[36m[2025-03-18 13:35:08 DEBUG] [caching:24][39m Building activity cache...
[36m[2025-03-18 13:35:08 DEBUG] [caching:35][39m Cached 3 activities
[32m[2025-03-18 13:35:08 INFO] [experiment:59][39m Validating the experiment's syntax
[36m[2025-03-18 13:35:08 DEBUG] [configuration:64][39m Loading configuration...
[36m[2025-03-18 13:35:08 DEBUG] [secret:79][39m Loading secrets...
[36m[2025-03-18 13:35:08 DEBUG] [secret:104][39m Done loading secrets
[32m[2025-03-18 13:35:08 INFO] [experiment:112][39m Experiment looks valid
[36m[2025-03-18 13:35:08 DEBUG] [caching:42][39m Clearing activities cache
[36m[2025-03-18 13:35:08 DEBUG] [run:224][39m Runtime strategies: hypothesis - default / rollbacks - default
[36m[2025-03-18 13:35:08 DEBUG] [caching:24][39m Building activity cache...
[36m[2025-03-18 13:35:08 DEBUG] [caching:35][39m Cached 3 activities
[36m[2025-03-18 13:35:08 DEBUG] [configuration:64][39m Loading configuration...
[36m[2025-03-18 13:35:08 DEBUG] [secret:79][39m Loading secrets...
[36m[2025-03-18 13:35:08 DEBUG] [secret:104][39m Done loading secrets
[36m[2025-03-18 13:35:08 DEBUG] [configuration:161][39m Loading dynamic configuration...
[32m[2025-03-18 13:35:08 INFO] [run:440][39m Running experiment: Privelege Scalation
[36m[2025-03-18 13:35:08 DEBUG] [__init__:67][39m Initializing controls
[32m[2025-03-18 13:35:08 INFO] [run:471][39m Steady-state strategy: default
[32m[2025-03-18 13:35:08 INFO] [run:477][39m Rollbacks strategy: default
[36m[2025-03-18 13:35:08 DEBUG] [__init__:472][39m No controls to apply on 'experiment'
[36m[2025-03-18 13:35:08 DEBUG] [run:654][39m Running steady-state hypothesis before the method
[32m[2025-03-18 13:35:08 INFO] [hypothesis:205][39m Steady state hypothesis: AWS GuardDuty detects the use of an instance profile credentials
[36m[2025-03-18 13:35:08 DEBUG] [__init__:472][39m No controls to apply on 'hypothesis'
[36m[2025-03-18 13:35:08 DEBUG] [__init__:472][39m No controls to apply on 'activity'
[32m[2025-03-18 13:35:08 INFO] [activity:232][39m Probe: GuarDuty-Findings
[36m[2025-03-18 13:35:08 DEBUG] [python:33][39m Activity 'GuarDuty-Findings' loaded from '/home/mmc/Descargas/devsecops-adversary-llm/SCE_Experiment/Runner/chaostk/lib/python3.12/site-packages/chaosaws/ec2/probes.py'
[36m[2025-03-18 13:35:08 DEBUG] [activity:260][39m   => succeeded with 'True'
[36m[2025-03-18 13:35:08 DEBUG] [__init__:472][39m No controls to apply on 'activity'
[36m[2025-03-18 13:35:08 DEBUG] [hypothesis:247][39m allowed tolerance is True
[32m[2025-03-18 13:35:08 INFO] [hypothesis:260][39m Steady state hypothesis is met!
[36m[2025-03-18 13:35:08 DEBUG] [__init__:472][39m No controls to apply on 'hypothesis'
[32m[2025-03-18 13:35:08 INFO] [run:778][39m Playing your experiment's method now...
[36m[2025-03-18 13:35:08 DEBUG] [__init__:472][39m No controls to apply on 'method'
[36m[2025-03-18 13:35:08 DEBUG] [__init__:472][39m No controls to apply on 'activity'
[32m[2025-03-18 13:35:08 INFO] [activity:232][39m Action: Creating_instance
[36m[2025-03-18 13:35:08 DEBUG] [python:33][39m Activity 'Creating_instance' loaded from '/home/mmc/Descargas/devsecops-adversary-llm/SCE_Experiment/Runner/chaostk/lib/python3.12/site-packages/chaosaws/ec2/actions.py'
[36m[2025-03-18 13:35:39 DEBUG] [__init__:472][39m No controls to apply on 'activity'
[36m[2025-03-18 13:35:39 DEBUG] [__init__:472][39m No controls to apply on 'method'
[33m[2025-03-18 13:35:39 WARNING] [run:556][39m Received a termination signal (Ctrl-C)...
[32m[2025-03-18 13:35:39 INFO] [run:598][39m Experiment ended with status: interrupted
[36m[2025-03-18 13:35:40 DEBUG] [__init__:472][39m No controls to apply on 'experiment'
[36m[2025-03-18 13:35:40 DEBUG] [__init__:106][39m Cleaning up controls
[36m[2025-03-18 13:35:40 DEBUG] [caching:42][39m Clearing activities cache
[36m[2025-03-18 13:35:43 DEBUG] [__init__:101][39m ###############################################################################
[36m[2025-03-18 13:35:43 DEBUG] [__init__:102][39m Running command 'run'
[36m[2025-03-18 13:35:43 DEBUG] [__init__:106][39m Using settings file '/home/mmc/.chaostoolkit/settings.yaml'
[36m[2025-03-18 13:35:43 DEBUG] [settings:31][39m The Chaos Toolkit settings file could not be found at '/home/mmc/.chaostoolkit/settings.yaml'.
[36m[2025-03-18 13:35:43 DEBUG] [__init__:472][39m No controls to apply on 'loader'
[36m[2025-03-18 13:35:43 DEBUG] [__init__:472][39m No controls to apply on 'loader'
[36m[2025-03-18 13:35:43 DEBUG] [caching:24][39m Building activity cache...
[36m[2025-03-18 13:35:43 DEBUG] [caching:35][39m Cached 3 activities
[32m[2025-03-18 13:35:43 INFO] [experiment:59][39m Validating the experiment's syntax
[36m[2025-03-18 13:35:43 DEBUG] [configuration:64][39m Loading configuration...
[36m[2025-03-18 13:35:43 DEBUG] [secret:79][39m Loading secrets...
[36m[2025-03-18 13:35:43 DEBUG] [secret:104][39m Done loading secrets
[32m[2025-03-18 13:35:43 INFO] [experiment:112][39m Experiment looks valid
[36m[2025-03-18 13:35:43 DEBUG] [caching:42][39m Clearing activities cache
[36m[2025-03-18 13:35:43 DEBUG] [run:224][39m Runtime strategies: hypothesis - default / rollbacks - default
[36m[2025-03-18 13:35:43 DEBUG] [caching:24][39m Building activity cache...
[36m[2025-03-18 13:35:43 DEBUG] [caching:35][39m Cached 3 activities
[36m[2025-03-18 13:35:43 DEBUG] [configuration:64][39m Loading configuration...
[36m[2025-03-18 13:35:43 DEBUG] [secret:79][39m Loading secrets...
[36m[2025-03-18 13:35:43 DEBUG] [secret:104][39m Done loading secrets
[36m[2025-03-18 13:35:43 DEBUG] [configuration:161][39m Loading dynamic configuration...
[32m[2025-03-18 13:35:43 INFO] [run:440][39m Running experiment: Privelege Scalation
[36m[2025-03-18 13:35:43 DEBUG] [__init__:67][39m Initializing controls
[32m[2025-03-18 13:35:43 INFO] [run:471][39m Steady-state strategy: default
[32m[2025-03-18 13:35:43 INFO] [run:477][39m Rollbacks strategy: default
[36m[2025-03-18 13:35:43 DEBUG] [__init__:472][39m No controls to apply on 'experiment'
[36m[2025-03-18 13:35:43 DEBUG] [run:654][39m Running steady-state hypothesis before the method
[32m[2025-03-18 13:35:43 INFO] [hypothesis:205][39m Steady state hypothesis: AWS GuardDuty detects the use of an instance profile credentials
[36m[2025-03-18 13:35:43 DEBUG] [__init__:472][39m No controls to apply on 'hypothesis'
[36m[2025-03-18 13:35:43 DEBUG] [__init__:472][39m No controls to apply on 'activity'
[32m[2025-03-18 13:35:43 INFO] [activity:232][39m Probe: GuarDuty-Findings
[36m[2025-03-18 13:35:43 DEBUG] [python:33][39m Activity 'GuarDuty-Findings' loaded from '/home/mmc/Descargas/devsecops-adversary-llm/SCE_Experiment/Runner/chaostk/lib/python3.12/site-packages/chaosaws/ec2/probes.py'
[36m[2025-03-18 13:35:43 DEBUG] [activity:260][39m   => succeeded with 'True'
[36m[2025-03-18 13:35:43 DEBUG] [__init__:472][39m No controls to apply on 'activity'
[36m[2025-03-18 13:35:43 DEBUG] [hypothesis:247][39m allowed tolerance is True
[32m[2025-03-18 13:35:43 INFO] [hypothesis:260][39m Steady state hypothesis is met!
[36m[2025-03-18 13:35:43 DEBUG] [__init__:472][39m No controls to apply on 'hypothesis'
[32m[2025-03-18 13:35:43 INFO] [run:778][39m Playing your experiment's method now...
[36m[2025-03-18 13:35:43 DEBUG] [__init__:472][39m No controls to apply on 'method'
[36m[2025-03-18 13:35:43 DEBUG] [__init__:472][39m No controls to apply on 'activity'
[32m[2025-03-18 13:35:43 INFO] [activity:232][39m Action: Creating_instance
[36m[2025-03-18 13:35:43 DEBUG] [python:33][39m Activity 'Creating_instance' loaded from '/home/mmc/Descargas/devsecops-adversary-llm/SCE_Experiment/Runner/chaostk/lib/python3.12/site-packages/chaosaws/ec2/actions.py'
[36m[2025-03-18 13:36:31 DEBUG] [activity:260][39m   => succeeded with 'True'
[36m[2025-03-18 13:36:31 DEBUG] [__init__:472][39m No controls to apply on 'activity'
[36m[2025-03-18 13:36:31 DEBUG] [__init__:472][39m No controls to apply on 'activity'
[32m[2025-03-18 13:36:31 INFO] [activity:232][39m Action: *******Extracting/Using credentials*******
[36m[2025-03-18 13:36:31 DEBUG] [python:33][39m Activity '*******Extracting/Using credentials*******' loaded from '/home/mmc/Descargas/devsecops-adversary-llm/SCE_Experiment/Runner/chaostk/lib/python3.12/site-packages/chaosaws/ec2/actions.py'
[36m[2025-03-18 13:36:31 DEBUG] [activity:260][39m   => succeeded with 'False'
[36m[2025-03-18 13:36:31 DEBUG] [__init__:472][39m No controls to apply on 'activity'
[36m[2025-03-18 13:36:31 DEBUG] [__init__:472][39m No controls to apply on 'method'
[36m[2025-03-18 13:36:31 DEBUG] [run:696][39m Running steady-state hypothesis after the method
[32m[2025-03-18 13:36:31 INFO] [hypothesis:205][39m Steady state hypothesis: AWS GuardDuty detects the use of an instance profile credentials
[36m[2025-03-18 13:36:31 DEBUG] [__init__:472][39m No controls to apply on 'hypothesis'
[36m[2025-03-18 13:36:31 DEBUG] [__init__:472][39m No controls to apply on 'activity'
[32m[2025-03-18 13:36:31 INFO] [activity:232][39m Probe: GuarDuty-Findings
[36m[2025-03-18 13:36:31 DEBUG] [python:33][39m Activity 'GuarDuty-Findings' loaded from '/home/mmc/Descargas/devsecops-adversary-llm/SCE_Experiment/Runner/chaostk/lib/python3.12/site-packages/chaosaws/ec2/probes.py'
[36m[2025-03-18 13:36:31 DEBUG] [activity:260][39m   => succeeded with 'True'
[36m[2025-03-18 13:36:31 DEBUG] [__init__:472][39m No controls to apply on 'activity'
[36m[2025-03-18 13:36:31 DEBUG] [hypothesis:247][39m allowed tolerance is True
[32m[2025-03-18 13:36:31 INFO] [hypothesis:260][39m Steady state hypothesis is met!
[36m[2025-03-18 13:36:31 DEBUG] [__init__:472][39m No controls to apply on 'hypothesis'
[32m[2025-03-18 13:36:31 INFO] [run:1072][39m Let's rollback...
[36m[2025-03-18 13:36:31 DEBUG] [__init__:472][39m No controls to apply on 'rollback'
[32m[2025-03-18 13:36:31 INFO] [rollback:33][39m No declared rollbacks, let's move on.
[36m[2025-03-18 13:36:31 DEBUG] [__init__:472][39m No controls to apply on 'rollback'
[32m[2025-03-18 13:36:31 INFO] [run:598][39m Experiment ended with status: completed
[36m[2025-03-18 13:36:31 DEBUG] [__init__:472][39m No controls to apply on 'experiment'
[36m[2025-03-18 13:36:31 DEBUG] [__init__:106][39m Cleaning up controls
[36m[2025-03-18 13:36:31 DEBUG] [caching:42][39m Clearing activities cache
[36m[2025-03-18 13:41:04 DEBUG] [__init__:101][39m ###############################################################################
[36m[2025-03-18 13:41:04 DEBUG] [__init__:102][39m Running command 'run'
[36m[2025-03-18 13:41:04 DEBUG] [__init__:106][39m Using settings file '/home/mmc/.chaostoolkit/settings.yaml'
[36m[2025-03-18 13:41:04 DEBUG] [settings:31][39m The Chaos Toolkit settings file could not be found at '/home/mmc/.chaostoolkit/settings.yaml'.
[36m[2025-03-18 13:41:04 DEBUG] [__init__:472][39m No controls to apply on 'loader'
[36m[2025-03-18 13:41:04 DEBUG] [__init__:472][39m No controls to apply on 'loader'
[36m[2025-03-18 13:41:04 DEBUG] [caching:24][39m Building activity cache...
[36m[2025-03-18 13:41:04 DEBUG] [caching:35][39m Cached 3 activities
[32m[2025-03-18 13:41:04 INFO] [experiment:59][39m Validating the experiment's syntax
[36m[2025-03-18 13:41:04 DEBUG] [configuration:64][39m Loading configuration...
[36m[2025-03-18 13:41:04 DEBUG] [secret:79][39m Loading secrets...
[36m[2025-03-18 13:41:04 DEBUG] [secret:104][39m Done loading secrets
[32m[2025-03-18 13:41:04 INFO] [experiment:112][39m Experiment looks valid
[36m[2025-03-18 13:41:04 DEBUG] [caching:42][39m Clearing activities cache
[36m[2025-03-18 13:41:04 DEBUG] [run:224][39m Runtime strategies: hypothesis - default / rollbacks - default
[36m[2025-03-18 13:41:04 DEBUG] [caching:24][39m Building activity cache...
[36m[2025-03-18 13:41:04 DEBUG] [caching:35][39m Cached 3 activities
[36m[2025-03-18 13:41:04 DEBUG] [configuration:64][39m Loading configuration...
[36m[2025-03-18 13:41:04 DEBUG] [secret:79][39m Loading secrets...
[36m[2025-03-18 13:41:04 DEBUG] [secret:104][39m Done loading secrets
[36m[2025-03-18 13:41:04 DEBUG] [configuration:161][39m Loading dynamic configuration...
[32m[2025-03-18 13:41:04 INFO] [run:440][39m Running experiment: Privelege Scalation
[36m[2025-03-18 13:41:04 DEBUG] [__init__:67][39m Initializing controls
[32m[2025-03-18 13:41:04 INFO] [run:471][39m Steady-state strategy: default
[32m[2025-03-18 13:41:04 INFO] [run:477][39m Rollbacks strategy: default
[36m[2025-03-18 13:41:04 DEBUG] [__init__:472][39m No controls to apply on 'experiment'
[36m[2025-03-18 13:41:04 DEBUG] [run:654][39m Running steady-state hypothesis before the method
[32m[2025-03-18 13:41:04 INFO] [hypothesis:205][39m Steady state hypothesis: AWS GuardDuty detects the use of an instance profile credentials
[36m[2025-03-18 13:41:04 DEBUG] [__init__:472][39m No controls to apply on 'hypothesis'
[36m[2025-03-18 13:41:04 DEBUG] [__init__:472][39m No controls to apply on 'activity'
[32m[2025-03-18 13:41:04 INFO] [activity:232][39m Probe: GuarDuty-Findings
[36m[2025-03-18 13:41:04 DEBUG] [python:33][39m Activity 'GuarDuty-Findings' loaded from '/home/mmc/Descargas/devsecops-adversary-llm/SCE_Experiment/Runner/chaostk/lib/python3.12/site-packages/chaosaws/ec2/probes.py'
[36m[2025-03-18 13:41:04 DEBUG] [activity:260][39m   => succeeded with 'True'
[36m[2025-03-18 13:41:04 DEBUG] [__init__:472][39m No controls to apply on 'activity'
[36m[2025-03-18 13:41:04 DEBUG] [hypothesis:247][39m allowed tolerance is True
[32m[2025-03-18 13:41:04 INFO] [hypothesis:260][39m Steady state hypothesis is met!
[36m[2025-03-18 13:41:04 DEBUG] [__init__:472][39m No controls to apply on 'hypothesis'
[32m[2025-03-18 13:41:04 INFO] [run:778][39m Playing your experiment's method now...
[36m[2025-03-18 13:41:04 DEBUG] [__init__:472][39m No controls to apply on 'method'
[36m[2025-03-18 13:41:04 DEBUG] [__init__:472][39m No controls to apply on 'activity'
[32m[2025-03-18 13:41:04 INFO] [activity:232][39m Action: Creating_instance
[36m[2025-03-18 13:41:04 DEBUG] [python:33][39m Activity 'Creating_instance' loaded from '/home/mmc/Descargas/devsecops-adversary-llm/SCE_Experiment/Runner/chaostk/lib/python3.12/site-packages/chaosaws/ec2/actions.py'
[36m[2025-03-18 13:41:47 DEBUG] [activity:260][39m   => succeeded with 'True'
[36m[2025-03-18 13:41:47 DEBUG] [__init__:472][39m No controls to apply on 'activity'
[36m[2025-03-18 13:41:47 DEBUG] [__init__:472][39m No controls to apply on 'activity'
[32m[2025-03-18 13:41:47 INFO] [activity:232][39m Action: *******Extracting/Using credentials*******
[36m[2025-03-18 13:41:47 DEBUG] [python:33][39m Activity '*******Extracting/Using credentials*******' loaded from '/home/mmc/Descargas/devsecops-adversary-llm/SCE_Experiment/Runner/chaostk/lib/python3.12/site-packages/chaosaws/ec2/actions.py'
[36m[2025-03-18 13:41:48 DEBUG] [activity:260][39m   => succeeded with 'False'
[36m[2025-03-18 13:41:48 DEBUG] [__init__:472][39m No controls to apply on 'activity'
[36m[2025-03-18 13:41:48 DEBUG] [__init__:472][39m No controls to apply on 'method'
[36m[2025-03-18 13:41:48 DEBUG] [run:696][39m Running steady-state hypothesis after the method
[32m[2025-03-18 13:41:48 INFO] [hypothesis:205][39m Steady state hypothesis: AWS GuardDuty detects the use of an instance profile credentials
[36m[2025-03-18 13:41:48 DEBUG] [__init__:472][39m No controls to apply on 'hypothesis'
[36m[2025-03-18 13:41:48 DEBUG] [__init__:472][39m No controls to apply on 'activity'
[32m[2025-03-18 13:41:48 INFO] [activity:232][39m Probe: GuarDuty-Findings
[36m[2025-03-18 13:41:48 DEBUG] [python:33][39m Activity 'GuarDuty-Findings' loaded from '/home/mmc/Descargas/devsecops-adversary-llm/SCE_Experiment/Runner/chaostk/lib/python3.12/site-packages/chaosaws/ec2/probes.py'
[36m[2025-03-18 13:41:48 DEBUG] [activity:260][39m   => succeeded with 'True'
[36m[2025-03-18 13:41:48 DEBUG] [__init__:472][39m No controls to apply on 'activity'
[36m[2025-03-18 13:41:48 DEBUG] [hypothesis:247][39m allowed tolerance is True
[32m[2025-03-18 13:41:48 INFO] [hypothesis:260][39m Steady state hypothesis is met!
[36m[2025-03-18 13:41:48 DEBUG] [__init__:472][39m No controls to apply on 'hypothesis'
[32m[2025-03-18 13:41:48 INFO] [run:1072][39m Let's rollback...
[36m[2025-03-18 13:41:48 DEBUG] [__init__:472][39m No controls to apply on 'rollback'
[32m[2025-03-18 13:41:48 INFO] [rollback:33][39m No declared rollbacks, let's move on.
[36m[2025-03-18 13:41:48 DEBUG] [__init__:472][39m No controls to apply on 'rollback'
[32m[2025-03-18 13:41:48 INFO] [run:598][39m Experiment ended with status: completed
[36m[2025-03-18 13:41:48 DEBUG] [__init__:472][39m No controls to apply on 'experiment'
[36m[2025-03-18 13:41:48 DEBUG] [__init__:106][39m Cleaning up controls
[36m[2025-03-18 13:41:48 DEBUG] [caching:42][39m Clearing activities cache
[36m[2025-03-18 13:48:20 DEBUG] [__init__:101][39m ###############################################################################
[36m[2025-03-18 13:48:20 DEBUG] [__init__:102][39m Running command 'run'
[36m[2025-03-18 13:48:20 DEBUG] [__init__:106][39m Using settings file '/home/mmc/.chaostoolkit/settings.yaml'
[36m[2025-03-18 13:48:20 DEBUG] [settings:31][39m The Chaos Toolkit settings file could not be found at '/home/mmc/.chaostoolkit/settings.yaml'.
[36m[2025-03-18 13:48:20 DEBUG] [__init__:472][39m No controls to apply on 'loader'
[36m[2025-03-18 13:48:20 DEBUG] [__init__:472][39m No controls to apply on 'loader'
[36m[2025-03-18 13:48:20 DEBUG] [caching:24][39m Building activity cache...
[36m[2025-03-18 13:48:20 DEBUG] [caching:35][39m Cached 3 activities
[32m[2025-03-18 13:48:20 INFO] [experiment:59][39m Validating the experiment's syntax
[36m[2025-03-18 13:48:20 DEBUG] [configuration:64][39m Loading configuration...
[36m[2025-03-18 13:48:20 DEBUG] [secret:79][39m Loading secrets...
[36m[2025-03-18 13:48:20 DEBUG] [secret:104][39m Done loading secrets
[32m[2025-03-18 13:48:20 INFO] [experiment:112][39m Experiment looks valid
[36m[2025-03-18 13:48:20 DEBUG] [caching:42][39m Clearing activities cache
[36m[2025-03-18 13:48:20 DEBUG] [run:224][39m Runtime strategies: hypothesis - default / rollbacks - default
[36m[2025-03-18 13:48:20 DEBUG] [caching:24][39m Building activity cache...
[36m[2025-03-18 13:48:20 DEBUG] [caching:35][39m Cached 3 activities
[36m[2025-03-18 13:48:20 DEBUG] [configuration:64][39m Loading configuration...
[36m[2025-03-18 13:48:20 DEBUG] [secret:79][39m Loading secrets...
[36m[2025-03-18 13:48:20 DEBUG] [secret:104][39m Done loading secrets
[36m[2025-03-18 13:48:20 DEBUG] [configuration:161][39m Loading dynamic configuration...
[32m[2025-03-18 13:48:20 INFO] [run:440][39m Running experiment: Privelege Scalation
[36m[2025-03-18 13:48:20 DEBUG] [__init__:67][39m Initializing controls
[32m[2025-03-18 13:48:20 INFO] [run:471][39m Steady-state strategy: default
[32m[2025-03-18 13:48:20 INFO] [run:477][39m Rollbacks strategy: default
[36m[2025-03-18 13:48:20 DEBUG] [__init__:472][39m No controls to apply on 'experiment'
[36m[2025-03-18 13:48:20 DEBUG] [run:654][39m Running steady-state hypothesis before the method
[32m[2025-03-18 13:48:20 INFO] [hypothesis:205][39m Steady state hypothesis: AWS GuardDuty detects the use of an instance profile credentials
[36m[2025-03-18 13:48:20 DEBUG] [__init__:472][39m No controls to apply on 'hypothesis'
[36m[2025-03-18 13:48:20 DEBUG] [__init__:472][39m No controls to apply on 'activity'
[32m[2025-03-18 13:48:20 INFO] [activity:232][39m Probe: GuarDuty-Findings
[36m[2025-03-18 13:48:20 DEBUG] [python:33][39m Activity 'GuarDuty-Findings' loaded from '/home/mmc/Descargas/devsecops-adversary-llm/SCE_Experiment/Runner/chaostk/lib/python3.12/site-packages/chaosaws/ec2/probes.py'
[36m[2025-03-18 13:48:20 DEBUG] [activity:260][39m   => succeeded with 'True'
[36m[2025-03-18 13:48:20 DEBUG] [__init__:472][39m No controls to apply on 'activity'
[36m[2025-03-18 13:48:20 DEBUG] [hypothesis:247][39m allowed tolerance is True
[32m[2025-03-18 13:48:20 INFO] [hypothesis:260][39m Steady state hypothesis is met!
[36m[2025-03-18 13:48:20 DEBUG] [__init__:472][39m No controls to apply on 'hypothesis'
[32m[2025-03-18 13:48:20 INFO] [run:778][39m Playing your experiment's method now...
[36m[2025-03-18 13:48:20 DEBUG] [__init__:472][39m No controls to apply on 'method'
[36m[2025-03-18 13:48:20 DEBUG] [__init__:472][39m No controls to apply on 'activity'
[32m[2025-03-18 13:48:20 INFO] [activity:232][39m Action: Creating_instance
[36m[2025-03-18 13:48:20 DEBUG] [python:33][39m Activity 'Creating_instance' loaded from '/home/mmc/Descargas/devsecops-adversary-llm/SCE_Experiment/Runner/chaostk/lib/python3.12/site-packages/chaosaws/ec2/actions.py'
[36m[2025-03-18 13:49:36 DEBUG] [activity:260][39m   => succeeded with 'True'
[36m[2025-03-18 13:49:36 DEBUG] [__init__:472][39m No controls to apply on 'activity'
[36m[2025-03-18 13:49:36 DEBUG] [__init__:472][39m No controls to apply on 'activity'
[32m[2025-03-18 13:49:36 INFO] [activity:232][39m Action: *******Extracting/Using credentials*******
[36m[2025-03-18 13:49:36 DEBUG] [python:33][39m Activity '*******Extracting/Using credentials*******' loaded from '/home/mmc/Descargas/devsecops-adversary-llm/SCE_Experiment/Runner/chaostk/lib/python3.12/site-packages/chaosaws/ec2/actions.py'
[36m[2025-03-18 13:49:36 DEBUG] [activity:260][39m   => succeeded with 'False'
[36m[2025-03-18 13:49:36 DEBUG] [__init__:472][39m No controls to apply on 'activity'
[36m[2025-03-18 13:49:36 DEBUG] [__init__:472][39m No controls to apply on 'method'
[36m[2025-03-18 13:49:36 DEBUG] [run:696][39m Running steady-state hypothesis after the method
[32m[2025-03-18 13:49:36 INFO] [hypothesis:205][39m Steady state hypothesis: AWS GuardDuty detects the use of an instance profile credentials
[36m[2025-03-18 13:49:36 DEBUG] [__init__:472][39m No controls to apply on 'hypothesis'
[36m[2025-03-18 13:49:36 DEBUG] [__init__:472][39m No controls to apply on 'activity'
[32m[2025-03-18 13:49:36 INFO] [activity:232][39m Probe: GuarDuty-Findings
[36m[2025-03-18 13:49:36 DEBUG] [python:33][39m Activity 'GuarDuty-Findings' loaded from '/home/mmc/Descargas/devsecops-adversary-llm/SCE_Experiment/Runner/chaostk/lib/python3.12/site-packages/chaosaws/ec2/probes.py'
[36m[2025-03-18 13:49:36 DEBUG] [activity:260][39m   => succeeded with 'True'
[36m[2025-03-18 13:49:36 DEBUG] [__init__:472][39m No controls to apply on 'activity'
[36m[2025-03-18 13:49:36 DEBUG] [hypothesis:247][39m allowed tolerance is True
[32m[2025-03-18 13:49:36 INFO] [hypothesis:260][39m Steady state hypothesis is met!
[36m[2025-03-18 13:49:36 DEBUG] [__init__:472][39m No controls to apply on 'hypothesis'
[32m[2025-03-18 13:49:36 INFO] [run:1072][39m Let's rollback...
[36m[2025-03-18 13:49:36 DEBUG] [__init__:472][39m No controls to apply on 'rollback'
[32m[2025-03-18 13:49:36 INFO] [rollback:33][39m No declared rollbacks, let's move on.
[36m[2025-03-18 13:49:36 DEBUG] [__init__:472][39m No controls to apply on 'rollback'
[32m[2025-03-18 13:49:36 INFO] [run:598][39m Experiment ended with status: completed
[36m[2025-03-18 13:49:36 DEBUG] [__init__:472][39m No controls to apply on 'experiment'
[36m[2025-03-18 13:49:36 DEBUG] [__init__:106][39m Cleaning up controls
[36m[2025-03-18 13:49:36 DEBUG] [caching:42][39m Clearing activities cache
